Workbook

Sheet MATCHES
A1: yt_id | B1: yt_title | C1: yt_dur_s | D1: playlist | E1: yt_topic | F1: local_file | G1: local_dur_s | H1: local_topic | I1: has_sub | J1: dur_score | K1: tfidf_score | L1: score | M1: match
A2: hQPyeZn-CEo | B2: 2. ¿Cómo presentar un reclamo? | C2: 33 | D2: Guía de Información 2018/2019 | Accesibilidad | E2: Accesibilidad | F2: DSC_0841 p.66.MOV | G2: 45.45 | H2: Accesibilidad | I2: TRUE | J2: 0.726 | K2: 0.367 | L2: 0.556 | M2: OK
A3: V-YJmvUkKog | B3: 3. Ley No. 962 de accesibilidad edilicia | C3: 47 | D3: Guía de Información 2018/2019 | Accesibilidad | E3: Accesibilidad | F3: DSC_0845 p.68 edificio accesible.MOV | G3: 52.55 | H3: Accesibilidad | I3: TRUE | J3: 0.894 | K3: 0.304 | L3: 0.58 | M3: OK
A4: Aza2d0yi5bs | B4: 5. Guía de Turismo Accesible | C4: 52 | D4: Guía de Información 2018/2019 | Accesibilidad | E4: Accesibilidad | F4: DSC_0847 p.69.MOV | G4: 54.15 | H4: Accesibilidad | I4: TRUE | J4: 0.96 | K4: 0.286 | L4: 0.593 | M4: OK
A5: Lq8JAf8gTI0 | B5: 2. Pase libre para viajar | C5: 44 | D5: Guía de Información 2018/2019 | Transporte | E5: Transporte | F5: DSC_0802 Pasaje gratis si.MOV | G5: 49.85 | H5: Transporte | I5: TRUE | J5: 0.883 | K5: 0.269 | L5: 0.557 | M5: OK
A6: vdp9Fh7jj-8 | B6: 6. ¿Cómo pedir la reserva de estacionamiento? ↓ | C6: 45 | D6: Guía de Información 2018/2019 | Transporte | E6: Transporte | F6: DSC_0824 Reserva estac CONFIRMAR SI.MOV | G6: 49.55 | H6: Accesibilidad | I6: TRUE | J6: 0.908 | K6: 0.241 | L6: 0.45 | M6: OK
A7: 52hONjN3AMk | B7: 1. COPIDIS Área Accesibilidad | C7: 56 | D7: Guía de Información 2018/2019 | Accesibilidad | E7: Accesibilidad | F7: DSC_0839 p.65 accesibilidad.MOV | G7: 63.76 | H7: Accesibilidad | I7: TRUE | J7: 0.878 | K7: 0.234 | L7: 0.536 | M7: OK
A8: 2iYRa7hKg2g | B8: 3. Pedir ayuda técnica | C8: 31 | D8: Guia de Información 2018/2019 | Servicios Sociales Zonales | E8: SSZonales | F8: DSC_0858 p. 75 ayuda tecnica.MOV | G8: 45.05 | H8: Accesibilidad | I8: TRUE | J8: 0.688 | K8: 0.231 | L8: 0.368 | M8: OK
A9: DQO5MhSq8ks | B9: 4. Perro guía o de asistencia | C9: 53 | D9: Guía de Información 2018/2019 | Transporte | E9: Transporte | F9: DSC_0812 Perro guia primera parte.MOV | G9: 48.95 | H9: Accesibilidad | I9: TRUE | J9: 0.924 | K9: 0.226 | L9: 0.448 | M9: OK
A10: -IdA4qbAncw | B10: 4. Vender en ferias artesanales | C10: 41 | D10: Guía de Información 2018/2019 | Trabajo | E10: Trabajo | F10: DSC_1034 ferias si.MOV | G10: 44.94 | H10: Trabajo | I10: TRUE | J10: 0.912 | K10: 0.223 | L10: 0.542 | M10: OK
A11: J6xUFDqW4BA | B11: 1. Organizaciones Sociedad Civil - OSC | C11: 50 | D11: Guía de Información 2018/2019 | Participación | E11: Participacion | F11: DSC_1042 osc si.MOV | G11: 56.46 | H11: Participacion | I11: TRUE | J11: 0.886 | K11: 0.214 | L11: 0.528
A12: S2KHEqDAia0 | B12: 2. Materia didáctico Braille ↓ | C12: 46 | D12: Guía de Información 2018/2019 | Educación | E12: Educacion | F12: DSC_0866 p.85 libros escolares accesibles.MOV | G12: 48.15 | H12: Educacion | I12: TRUE | J12: 0.955 | K12: 0.208 | L12: 0.549 | M12: OK
A13: jcWSZirq1ho | B13: 7. Afiliarse a Incluir Salud | C13: 49 | D13: Guía de Información 2018/2019 | Salud | E13: Salud | F13: DSC_0799 Incluir Salud tramite si.MOV | G13: 51.85 | H13: CUD | I13: TRUE | J13: 0.945 | K13: 0.189 | L13: 0.435 | M13: OK
A14: wSd8jKV42Y8 | B14: 1. Apoyos Educación | C14: 40 | D14: Guía de Información 2018/2019 | Educación | E14: Educacion | F14: DSC_0862 p. 85 apoyos copidis educacion.MOV | G14: 50.65 | H14: Educacion | I14: TRUE | J14: 0.79 | K14: 0.179 | L14: 0.475 | M14: OK
A15: kcChz0qrXZs | B15: 5. Símbolo Internacional de Acceso | C15: 66 | D15: Guía de Información 2018/2019 | Transporte | E15: Transporte | F15: DSC_0818 Simbolo si mejor.MOV | G15: 90.99 | H15: Accesibilidad | I15: TRUE | J15: 0.725 | K15: 0.177 | L15: 0.351
A16: 4T68Q7fSeA4 | B16: 3. Registro Pequeños Comercios | C16: 55 | D16: Guía de Información 2018/2019 | Trabajo | E16: Trabajo | F16: DSC_1031pquenos com si.MOV | G16: 67.97 | H16: Trabajo | I16: TRUE | J16: 0.809 | K16: 0.174 | L16: 0.479 | M16: OK
A17: _j3n-b6Fc_A | B17: 1. Registro Único Laboral - RUL | C17: 68 | D17: Guía de Información 2018/2019 | Trabajo | E17: Trabajo | F17: DSC_0884 p.108 rul.MOV | G17: 74.07 | H17: Trabajo | I17: TRUE | J17: 0.918 | K17: 0.165 | L17: 0.512 | M17: OK
A18: ZbjWSR5fl88 | B18: 6. App BA Accesible | C18: 64 | D18: Guía de Información 2018/2019 | Accesibilidad | E18: Accesibilidad | F18: DSC_0848 p.70 BAapp.MOV | G18: 69.67 | H18: Accesibilidad | I18: TRUE | J18: 0.919 | K18: 0.138 | L18: 0.497 | M18: OK
A19: 5J9xY8gOdUY | B19: 4. Apoyos Ministerio de Educación | C19: 37 | D19: Guía de Información 2018/2019 | Educación | E19: Educacion | F19: DSC_0873 p.87 que apoyos te da el Ministerio de Educacion.MOV | G19: 40.14 | H19: Educacion | I19: TRUE | J19: 0.922 | K19: 0.136 | L19: 0.497 | M19: OK
A20: kMOBrkojQbw | B20: 1. Banco de Elementos Ortopédicos - BEO | C20: 29 | D20: Guía de Información 2018/2019 | Vida Independiente | E20: VidaIndependiente | F20: DSC_0882 p,105 beo.MOV | G20: 32.43 | H20: Salud | I20: TRUE | J20: 0.894 | K20: 0.136 | L20: 0.388 | M20: OK
A21: u07hL-EzTpY | B21: 1. Programa Hogares | C21: 52 | D21: Guia de Información 2018/2019 | Servicios Sociales Zonales | E21: SSZonales | F21: DSC_0851 p.73.MOV | G21: 55.66 | H21: Accesibilidad | I21: TRUE | J21: 0.934 | K21: 0.13 | L21: 0.399 | M21: OK
A22: OTmV28NGG5I | B22: 2 - Fortalecimiento ↓ | C22: 25 | D22: Guía de Información 2018/2019 | Participación | E22: Participacion | F22: DSC_1044 fortalecimiento si.MOV | G22: 38.04 | H22: Participacion | I22: TRUE | J22: 0.657 | K22: 0.118 | L22: 0.395
A23: T_vgQJhMWf8 | B23: 2. Apoyos del Gobierno de la Nación | C23: 44 | D23: Guia de Información 2018/2019 | Servicios Sociales Zonales | E23: SSZonales | F23: DSC_0856 p.74.MOV | G23: 51.25 | H23: Accesibilidad | I23: TRUE | J23: 0.859 | K23: 0.108 | L23: 0.36 | M23: OK
A24: Vil9KHTo8p8 | B24: 2. Qué son las prestaciones básicas de salud | C24: 32 | D24: Guía de Información 2018/2019 | Salud | E24: Salud | F24: DSC_0798 Incluir Salud que es si.MOV | G24: 36.34 | H24: Salud | I24: TRUE | J24: 0.881 | K24: 0.101 | L24: 0.464
A25: XxDsNzglSzU | B25: 6. Incluir Salud | C25: 23 | D25: Guía de Información 2018/2019 | Salud | E25: Salud | F25: DSC_0798 Incluir Salud que es si.MOV | G25: 36.34 | H25: Salud | I25: TRUE | J25: 0.881 | K25: 0.101 | L25: 0.464 | M25: OK
A26: oE49uoxSRr8 | B26: 4. Reclamos online | C26: 27 | D26: Guía de Información 2018/2019 | Accesibilidad | E26: Accesibilidad | F26: DSC_0846 p.68 lugr publico.MOV | G26: 31.53 | H26: Accesibilidad | I26: TRUE | J26: 0.856 | K26: 0.083 | L26: 0.445 | M26: OK
A27: JxP7w7g28D4 | B27: 6. Apoyos y ajustes razonables | C27: 39 | D27: Guía de Información 2018/2019 | Certificado Único de Discapacidad - CUD | E27: CUD | F27: DSC_0738 Apoyo3 final.MOV | G27: 42.24 | H27: unknown | I27: FALSE | J27: 0.923 | K27: 0.04 | L27: 0.345 | M27: OK
A28: bw6hm44CRQk | B28: 1. Prestaciones básicas de salud | C28: 15 | D28: Guía de Información 2018/2019 | Salud | E28: Salud | F28: DSC_0702 Titulo Salud Transp Acc.MOV | G28: 12.61 | H28: Salud | I28: FALSE | J28: 0.841 | K28: 0.021 | L28: 0.406
A29: bw6hm44CRQk | B29: 1. Prestaciones básicas de salud | C29: 15 | D29: Guía de Información 2018/2019 | Salud | E29: Salud | F29: DSC_0726 salud2 si.MOV | G29: 20.12 | H29: Salud | I29: FALSE | J29: 0.875 | K29: 0 | L29: 0.406 | M29: OK
A30: AU3OdF0iNv0 | B30: 5. Cobertura Porteña Salud | C30: 34 | D30: Guía de Información 2018/2019 | Salud | E30: Salud | F30: DSC_0789 Serv Salud basico si.MOV | G30: 33.13 | H30: Salud | I30: FALSE | J30: 0.974 | K30: 0.016 | L30: 0.45
A31: Vil9KHTo8p8 | B31: 2. Qué son las prestaciones básicas de salud | C31: 32 | D31: Guía de Información 2018/2019 | Salud | E31: Salud | F31: DSC_0789 Serv Salud basico si.MOV | G31: 33.13 | H31: Salud | I31: FALSE | J31: 0.974 | K31: 0.016 | L31: 0.45 | M31: OK
A32: Wns-CUyyQL0 | B32: 7. Materiales didácticos | C32: 29 | D32: Guía de Información 2018/2019 | Educación | E32: Educacion | F32: DSC_0878 p. 95 escuelas hospitalarias.MOV | G32: 30.63 | H32: Educacion | I32: TRUE | J32: 0.947 | K32: 0.013 | L32: 0.439
A33: QlS5zsPqw3k | B33: 6. Escuela hospitalaria o domiciliaria | C33: 27 | D33: Guía de Información 2018/2019 | Educación | E33: Educacion | F33: DSC_0878 p. 95 escuelas hospitalarias.MOV | G33: 30.63 | H33: Educacion | I33: TRUE | J33: 0.947 | K33: 0.013 | L33: 0.439 | M33: OK
A34: jomsMKgYkyQ | B34: 3. Pedir prestaciones básicas de salud | C34: 37 | D34: Guía de Información 2018/2019 | Salud | E34: Salud | F34: DSC_0797 Plan Salud Ciudad si.MOV | G34: 38.14 | H34: Salud | I34: TRUE | J34: 0.97 | K34: 0.008 | L34: 0.444
A35: jomsMKgYkyQ | B35: 3. Pedir prestaciones básicas de salud | C35: 37 | D35: Guía de Información 2018/2019 | Salud | E35: Salud | F35: DSC_0792 Serv Salud basico si | H35: Salud | M35: OK
A36: AU3OdF0iNv0 | B36: 5. Cobertura Porteña Salud | C36: 34 | D36: Guía de Información 2018/2019 | Salud | E36: Salud | F36: DSC_0797 Plan Salud Ciudad si.MOV | G36: 38.14 | H36: Salud | I36: TRUE | J36: 0.97 | K36: 0.008 | L36: 0.444 | M36: OK
A37: 6lWq6bCXwTY | B37: 8. ¿Que podes hacer si perdiste o te robaron el CUD? | C37: 58 | D37: Guía de Información 2018/2019 | Certificado Único de Discapacidad - CUD | E37: CUD | F37: DSC_0826 Franquicia si.MOV | G37: 41.04 | H37: BeneficiosFiscales | I37: TRUE | J37: 0.708 | K37: 0.005 | L37: 0.25
A38: gSe9tkhgOT0 | B38: 7. Franquicias | C38: 37 | D38: Guía de Información 2018/2019 | Transporte | E38: Transporte | F38: DSC_0826 Franquicia si.MOV | G38: 41.04 | H38: BeneficiosFiscales | I38: TRUE | J38: 0.708 | K38: 0.005 | L38: 0.25 | M38: OK
A39: bg8ySVMa71A | B39: Circuito 8 y 9: Provincia de Buenos Aires/ Mar del Plata | C39: 60 | D39: Guía de Turismo 2018/2019 | E39: Turismo | F39: DSC_0795 Sin rta si.MOV | G39: 60.26 | H39: unknown | I39: TRUE | J39: 0.996 | K39: 0 | L39: 0.349
A40: qxy6Wv4NRB4 | B40: 1. ¿Qué es el certificado Único de Discapacidad? | C40: 23 | D40: Guía de Información 2018/2019 | Certificado Único de Discapacidad - CUD | E40: CUD | F40: DSC_0724 CUD uso5 si.MOV | G40: 23.12 | H40: CUD | I40: FALSE | J40: 0.995 | K40: 0 | L40: 0.448
...

Sheet CURADOS
A1: =IFERROR(__xludf.DUMMYFUNCTION("{ MATCHES!A1:M1; SORT( FILTER(MATCHES!A2:M1000, MATCHES!M2:M1000=""OK""), 4, TRUE, 2, TRUE ) }"),"yt_id") | B1: =IFERROR(__xludf.DUMMYFUNCTION("""COMPUTED_VALUE"""),"yt_title") | C1: =IFERROR(__xludf.DUMMYFUNCTION("""COMPUTED_VALUE"""),"yt_dur_s") | D1: =IFERROR(__xludf.DUMMYFUNCTION("""COMPUTED_VALUE"""),"playlist") | E1: =IFERROR(__xludf.DUMMYFUNCTION("""COMPUTED_VALUE"""),"yt_topic") | F1: =IFERROR(__xludf.DUMMYFUNCTION("""COMPUTED_VALUE"""),"local_file") | G1: =IFERROR(__xludf.DUMMYFUNCTION("""COMPUTED_VALUE"""),"local_dur_s") | H1: =IFERROR(__xludf.DUMMYFUNCTION("""COMPUTED_VALUE"""),"local_topic") | I1: =IFERROR(__xludf.DUMMYFUNCTION("""COMPUTED_VALUE"""),"has_sub") | J1: =IFERROR(__xludf.DUMMYFUNCTION("""COMPUTED_VALUE"""),"dur_score") | K1: =IFERROR(__xludf.DUMMYFUNCTION("""COMPUTED_VALUE"""),"tfidf_score") | L1: =IFERROR(__xludf.DUMMYFUNCTION("""COMPUTED_VALUE"""),"score") | M1: =IFERROR(__xludf.DUMMYFUNCTION("""COMPUTED_VALUE"""),"match")
A2: =IFERROR(__xludf.DUMMYFUNCTION("""COMPUTED_VALUE"""),"DQO5MhSq8ks") | B2: =IFERROR(__xludf.DUMMYFUNCTION("""COMPUTED_VALUE""")," 4. Perro guía o de asistencia") | C2: =IFERROR(__xludf.DUMMYFUNCTION("""COMPUTED_VALUE"""),53.0) | D2: =IFERROR(__xludf.DUMMYFUNCTION("""COMPUTED_VALUE""")," | Guía de Información 2018/2019 | Transporte") | E2: =IFERROR(__xludf.DUMMYFUNCTION("""COMPUTED_VALUE"""),"Transporte") | F2: =IFERROR(__xludf.DUMMYFUNCTION("""COMPUTED_VALUE"""),"DSC_0812 Perro guia primera parte.MOV") | G2: =IFERROR(__xludf.DUMMYFUNCTION("""COMPUTED_VALUE"""),48.95) | H2: =IFERROR(__xludf.DUMMYFUNCTION("""COMPUTED_VALUE"""),"Accesibilidad") | I2: =IFERROR(__xludf.DUMMYFUNCTION("""COMPUTED_VALUE"""),TRUE) | J2: =IFERROR(__xludf.DUMMYFUNCTION("""COMPUTED_VALUE"""),0.924) | K2: =IFERROR(__xludf.DUMMYFUNCTION("""COMPUTED_VALUE"""),0.226) | L2: =IFERROR(__xludf.DUMMYFUNCTION("""COMPUTED_VALUE"""),0.448) | M2: =IFERROR(__xludf.DUMMYFUNCTION("""COMPUTED_VALUE"""),"OK")
A3: =IFERROR(__xludf.DUMMYFUNCTION("""COMPUTED_VALUE"""),"52hONjN3AMk") | B3: =IFERROR(__xludf.DUMMYFUNCTION("""COMPUTED_VALUE"""),"1. COPIDIS Área Accesibilidad") | C3: =IFERROR(__xludf.DUMMYFUNCTION("""COMPUTED_VALUE"""),56.0) | D3: =IFERROR(__xludf.DUMMYFUNCTION("""COMPUTED_VALUE"""),"Guía de Información 2018/2019 | Accesibilidad") | E3: =IFERROR(__xludf.DUMMYFUNCTION("""COMPUTED_VALUE"""),"Accesibilidad") | F3: =IFERROR(__xludf.DUMMYFUNCTION("""COMPUTED_VALUE"""),"DSC_0839 p.65 accesibilidad.MOV") | G3: =IFERROR(__xludf.DUMMYFUNCTION("""COMPUTED_VALUE"""),63.76) | H3: =IFERROR(__xludf.DUMMYFUNCTION("""COMPUTED_VALUE"""),"Accesibilidad") | I3: =IFERROR(__xludf.DUMMYFUNCTION("""COMPUTED_VALUE"""),TRUE) | J3: =IFERROR(__xludf.DUMMYFUNCTION("""COMPUTED_VALUE"""),0.878) | K3: =IFERROR(__xludf.DUMMYFUNCTION("""COMPUTED_VALUE"""),0.234) | L3: =IFERROR(__xludf.DUMMYFUNCTION("""COMPUTED_VALUE"""),0.536) | M3: =IFERROR(__xludf.DUMMYFUNCTION("""COMPUTED_VALUE"""),"OK")
A4: =IFERROR(__xludf.DUMMYFUNCTION("""COMPUTED_VALUE"""),"hQPyeZn-CEo") | B4: =IFERROR(__xludf.DUMMYFUNCTION("""COMPUTED_VALUE"""),"2. ¿Cómo presentar un reclamo?") | C4: =IFERROR(__xludf.DUMMYFUNCTION("""COMPUTED_VALUE"""),33.0) | D4: =IFERROR(__xludf.DUMMYFUNCTION("""COMPUTED_VALUE"""),"Guía de Información 2018/2019 | Accesibilidad") | E4: =IFERROR(__xludf.DUMMYFUNCTION("""COMPUTED_VALUE"""),"Accesibilidad") | F4: =IFERROR(__xludf.DUMMYFUNCTION("""COMPUTED_VALUE"""),"DSC_0841 p.66.MOV") | G4: =IFERROR(__xludf.DUMMYFUNCTION("""COMPUTED_VALUE"""),45.45) | H4: =IFERROR(__xludf.DUMMYFUNCTION("""COMPUTED_VALUE"""),"Accesibilidad") | I4: =IFERROR(__xludf.DUMMYFUNCTION("""COMPUTED_VALUE"""),TRUE) | J4: =IFERROR(__xludf.DUMMYFUNCTION("""COMPUTED_VALUE"""),0.726) | K4: =IFERROR(__xludf.DUMMYFUNCTION("""COMPUTED_VALUE"""),0.367) | L4: =IFERROR(__xludf.DUMMYFUNCTION("""COMPUTED_VALUE"""),0.556) | M4: =IFERROR(__xludf.DUMMYFUNCTION("""COMPUTED_VALUE"""),"OK")
A5: =IFERROR(__xludf.DUMMYFUNCTION("""COMPUTED_VALUE"""),"V-YJmvUkKog") | B5: =IFERROR(__xludf.DUMMYFUNCTION("""COMPUTED_VALUE"""),"3. Ley No. 962 de accesibilidad edilicia") | C5: =IFERROR(__xludf.DUMMYFUNCTION("""COMPUTED_VALUE"""),47.0) | D5: =IFERROR(__xludf.DUMMYFUNCTION("""COMPUTED_VALUE"""),"Guía de Información 2018/2019 | Accesibilidad") | E5: =IFERROR(__xludf.DUMMYFUNCTION("""COMPUTED_VALUE"""),"Accesibilidad") | F5: =IFERROR(__xludf.DUMMYFUNCTION("""COMPUTED_VALUE"""),"DSC_0845 p.68 edificio accesible.MOV") | G5: =IFERROR(__xludf.DUMMYFUNCTION("""COMPUTED_VALUE"""),52.55) | H5: =IFERROR(__xludf.DUMMYFUNCTION("""COMPUTED_VALUE"""),"Accesibilidad") | I5: =IFERROR(__xludf.DUMMYFUNCTION("""COMPUTED_VALUE"""),TRUE) | J5: =IFERROR(__xludf.DUMMYFUNCTION("""COMPUTED_VALUE"""),0.894) | K5: =IFERROR(__xludf.DUMMYFUNCTION("""COMPUTED_VALUE"""),0.304) | L5: =IFERROR(__xludf.DUMMYFUNCTION("""COMPUTED_VALUE"""),0.58) | M5: =IFERROR(__xludf.DUMMYFUNCTION("""COMPUTED_VALUE"""),"OK")
A6: =IFERROR(__xludf.DUMMYFUNCTION("""COMPUTED_VALUE"""),"oE49uoxSRr8") | B6: =IFERROR(__xludf.DUMMYFUNCTION("""COMPUTED_VALUE"""),"4. Reclamos online") | C6: =IFERROR(__xludf.DUMMYFUNCTION("""COMPUTED_VALUE"""),27.0) | D6: =IFERROR(__xludf.DUMMYFUNCTION("""COMPUTED_VALUE"""),"Guía de Información 2018/2019 | Accesibilidad") | E6: =IFERROR(__xludf.DUMMYFUNCTION("""COMPUTED_VALUE"""),"Accesibilidad") | F6: =IFERROR(__xludf.DUMMYFUNCTION("""COMPUTED_VALUE"""),"DSC_0846 p.68 lugr publico.MOV") | G6: =IFERROR(__xludf.DUMMYFUNCTION("""COMPUTED_VALUE"""),31.53) | H6: =IFERROR(__xludf.DUMMYFUNCTION("""COMPUTED_VALUE"""),"Accesibilidad") | I6: =IFERROR(__xludf.DUMMYFUNCTION("""COMPUTED_VALUE"""),TRUE) | J6: =IFERROR(__xludf.DUMMYFUNCTION("""COMPUTED_VALUE"""),0.856) | K6: =IFERROR(__xludf.DUMMYFUNCTION("""COMPUTED_VALUE"""),0.083) | L6: =IFERROR(__xludf.DUMMYFUNCTION("""COMPUTED_VALUE"""),0.445) | M6: =IFERROR(__xludf.DUMMYFUNCTION("""COMPUTED_VALUE"""),"OK")
A7: =IFERROR(__xludf.DUMMYFUNCTION("""COMPUTED_VALUE"""),"Aza2d0yi5bs") | B7: =IFERROR(__xludf.DUMMYFUNCTION("""COMPUTED_VALUE"""),"5. Guía de Turismo Accesible") | C7: =IFERROR(__xludf.DUMMYFUNCTION("""COMPUTED_VALUE"""),52.0) | D7: =IFERROR(__xludf.DUMMYFUNCTION("""COMPUTED_VALUE"""),"Guía de Información 2018/2019 | Accesibilidad") | E7: =IFERROR(__xludf.DUMMYFUNCTION("""COMPUTED_VALUE"""),"Accesibilidad") | F7: =IFERROR(__xludf.DUMMYFUNCTION("""COMPUTED_VALUE"""),"DSC_0847 p.69.MOV") | G7: =IFERROR(__xludf.DUMMYFUNCTION("""COMPUTED_VALUE"""),54.15) | H7: =IFERROR(__xludf.DUMMYFUNCTION("""COMPUTED_VALUE"""),"Accesibilidad") | I7: =IFERROR(__xludf.DUMMYFUNCTION("""COMPUTED_VALUE"""),TRUE) | J7: =IFERROR(__xludf.DUMMYFUNCTION("""COMPUTED_VALUE"""),0.96) | K7: =IFERROR(__xludf.DUMMYFUNCTION("""COMPUTED_VALUE"""),0.286) | L7: =IFERROR(__xludf.DUMMYFUNCTION("""COMPUTED_VALUE"""),0.593) | M7: =IFERROR(__xludf.DUMMYFUNCTION("""COMPUTED_VALUE"""),"OK")
A8: =IFERROR(__xludf.DUMMYFUNCTION("""COMPUTED_VALUE"""),"ZbjWSR5fl88") | B8: =IFERROR(__xludf.DUMMYFUNCTION("""COMPUTED_VALUE"""),"6. App BA Accesible") | C8: =IFERROR(__xludf.DUMMYFUNCTION("""COMPUTED_VALUE"""),64.0) | D8: =IFERROR(__xludf.DUMMYFUNCTION("""COMPUTED_VALUE"""),"Guía de Información 2018/2019 | Accesibilidad") | E8: =IFERROR(__xludf.DUMMYFUNCTION("""COMPUTED_VALUE"""),"Accesibilidad") | F8: =IFERROR(__xludf.DUMMYFUNCTION("""COMPUTED_VALUE"""),"DSC_0848 p.70 BAapp.MOV") | G8: =IFERROR(__xludf.DUMMYFUNCTION("""COMPUTED_VALUE"""),69.67) | H8: =IFERROR(__xludf.DUMMYFUNCTION("""COMPUTED_VALUE"""),"Accesibilidad") | I8: =IFERROR(__xludf.DUMMYFUNCTION("""COMPUTED_VALUE"""),TRUE) | J8: =IFERROR(__xludf.DUMMYFUNCTION("""COMPUTED_VALUE"""),0.919) | K8: =IFERROR(__xludf.DUMMYFUNCTION("""COMPUTED_VALUE"""),0.138) | L8: =IFERROR(__xludf.DUMMYFUNCTION("""COMPUTED_VALUE"""),0.497) | M8: =IFERROR(__xludf.DUMMYFUNCTION("""COMPUTED_VALUE"""),"OK")
A9: =IFERROR(__xludf.DUMMYFUNCTION("""COMPUTED_VALUE"""),"qxy6Wv4NRB4") | B9: =IFERROR(__xludf.DUMMYFUNCTION("""COMPUTED_VALUE"""),"1. ¿Qué es el certificado Único de Discapacidad?") | C9: =IFERROR(__xludf.DUMMYFUNCTION("""COMPUTED_VALUE"""),23.0) | D9: =IFERROR(__xludf.DUMMYFUNCTION("""COMPUTED_VALUE"""),"Guía de Información 2018/2019 | Certificado Único de Discapacidad - CUD") | E9: =IFERROR(__xludf.DUMMYFUNCTION("""COMPUTED_VALUE"""),"CUD") | F9: =IFERROR(__xludf.DUMMYFUNCTION("""COMPUTED_VALUE"""),"DSC_0710 CUD3 si (ver).MOV") | G9: =IFERROR(__xludf.DUMMYFUNCTION("""COMPUTED_VALUE"""),29.43) | H9: =IFERROR(__xludf.DUMMYFUNCTION("""COMPUTED_VALUE"""),"CUD") | I9: =IFERROR(__xludf.DUMMYFUNCTION("""COMPUTED_VALUE"""),FALSE) | J9: =IFERROR(__xludf.DUMMYFUNCTION("""COMPUTED_VALUE"""),0.815) | K9: =IFERROR(__xludf.DUMMYFUNCTION("""COMPUTED_VALUE"""),0.0) | L9: =IFERROR(__xludf.DUMMYFUNCTION("""COMPUTED_VALUE"""),0.385) | M9: =IFERROR(__xludf.DUMMYFUNCTION("""COMPUTED_VALUE"""),"OK")
A10: =IFERROR(__xludf.DUMMYFUNCTION("""COMPUTED_VALUE"""),"u4R2ZtoexMU") | B10: =IFERROR(__xludf.DUMMYFUNCTION("""COMPUTED_VALUE"""),"2. Persona con discapacidad") | C10: =IFERROR(__xludf.DUMMYFUNCTION("""COMPUTED_VALUE"""),35.0) | D10: =IFERROR(__xludf.DUMMYFUNCTION("""COMPUTED_VALUE"""),"Guía de Información 2018/2019 | Certificado Único de Discapacidad - CUD") | E10: =IFERROR(__xludf.DUMMYFUNCTION("""COMPUTED_VALUE"""),"CUD") | F10: =IFERROR(__xludf.DUMMYFUNCTION("""COMPUTED_VALUE"""),"DSC_0715 PCD5 si") | M10: =IFERROR(__xludf.DUMMYFUNCTION("""COMPUTED_VALUE"""),"OK")
A11: =IFERROR(__xludf.DUMMYFUNCTION("""COMPUTED_VALUE"""),"WnBynb92GWE") | B11: =IFERROR(__xludf.DUMMYFUNCTION("""COMPUTED_VALUE"""),"3. ¿Dónde pedís tu CUD?") | C11: =IFERROR(__xludf.DUMMYFUNCTION("""COMPUTED_VALUE"""),49.0) | D11: =IFERROR(__xludf.DUMMYFUNCTION("""COMPUTED_VALUE"""),"Guía de Información 2018/2019 | Certificado Único de Discapacidad - CUD") | E11: =IFERROR(__xludf.DUMMYFUNCTION("""COMPUTED_VALUE"""),"CUD") | F11: =IFERROR(__xludf.DUMMYFUNCTION("""COMPUTED_VALUE"""),"DSC_0718 CUD tram3 no c.MOV") | G11: =IFERROR(__xludf.DUMMYFUNCTION("""COMPUTED_VALUE"""),52.75) | H11: =IFERROR(__xludf.DUMMYFUNCTION("""COMPUTED_VALUE"""),"CUD") | I11: =IFERROR(__xludf.DUMMYFUNCTION("""COMPUTED_VALUE"""),FALSE) | J11: =IFERROR(__xludf.DUMMYFUNCTION("""COMPUTED_VALUE"""),0.942) | K11: =IFERROR(__xludf.DUMMYFUNCTION("""COMPUTED_VALUE"""),0.0) | L11: =IFERROR(__xludf.DUMMYFUNCTION("""COMPUTED_VALUE"""),0.33) | M11: =IFERROR(__xludf.DUMMYFUNCTION("""COMPUTED_VALUE"""),"OK")
A12: =IFERROR(__xludf.DUMMYFUNCTION("""COMPUTED_VALUE"""),"bx3o-WISVPk") | B12: =IFERROR(__xludf.DUMMYFUNCTION("""COMPUTED_VALUE"""),"4. ¿Para qué sirve el CUD?") | C12: =IFERROR(__xludf.DUMMYFUNCTION("""COMPUTED_VALUE"""),17.0) | D12: =IFERROR(__xludf.DUMMYFUNCTION("""COMPUTED_VALUE"""),"Guía de Información 2018/2019 | Certificado Único de Discapacidad - CUD") | E12: =IFERROR(__xludf.DUMMYFUNCTION("""COMPUTED_VALUE"""),"CUD") | F12: =IFERROR(__xludf.DUMMYFUNCTION("""COMPUTED_VALUE"""),"DSC_0719 CUD tram4 si.MOV") | G12: =IFERROR(__xludf.DUMMYFUNCTION("""COMPUTED_VALUE"""),24.12) | H12: =IFERROR(__xludf.DUMMYFUNCTION("""COMPUTED_VALUE"""),"CUD") | I12: =IFERROR(__xludf.DUMMYFUNCTION("""COMPUTED_VALUE"""),FALSE) | J12: =IFERROR(__xludf.DUMMYFUNCTION("""COMPUTED_VALUE"""),0.995) | K12: =IFERROR(__xludf.DUMMYFUNCTION("""COMPUTED_VALUE"""),0.0) | L12: =IFERROR(__xludf.DUMMYFUNCTION("""COMPUTED_VALUE"""),0.348) | M12: =IFERROR(__xludf.DUMMYFUNCTION("""COMPUTED_VALUE"""),"OK")
A13: =IFERROR(__xludf.DUMMYFUNCTION("""COMPUTED_VALUE"""),"JxP7w7g28D4") | B13: =IFERROR(__xludf.DUMMYFUNCTION("""COMPUTED_VALUE"""),"6. Apoyos y ajustes razonables") | C13: =IFERROR(__xludf.DUMMYFUNCTION("""COMPUTED_VALUE"""),39.0) | D13: =IFERROR(__xludf.DUMMYFUNCTION("""COMPUTED_VALUE"""),"Guía de Información 2018/2019 | Certificado Único de Discapacidad - CUD") | E13: =IFERROR(__xludf.DUMMYFUNCTION("""COMPUTED_VALUE"""),"CUD") | F13: =IFERROR(__xludf.DUMMYFUNCTION("""COMPUTED_VALUE"""),"DSC_0738 Apoyo3 final.MOV") | G13: =IFERROR(__xludf.DUMMYFUNCTION("""COMPUTED_VALUE"""),42.24) | H13: =IFERROR(__xludf.DUMMYFUNCTION("""COMPUTED_VALUE"""),"unknown") | I13: =IFERROR(__xludf.DUMMYFUNCTION("""COMPUTED_VALUE"""),FALSE) | J13: =IFERROR(__xludf.DUMMYFUNCTION("""COMPUTED_VALUE"""),0.923) | K13: =IFERROR(__xludf.DUMMYFUNCTION("""COMPUTED_VALUE"""),0.04) | L13: =IFERROR(__xludf.DUMMYFUNCTION("""COMPUTED_VALUE"""),0.345) | M13: =IFERROR(__xludf.DUMMYFUNCTION("""COMPUTED_VALUE"""),"OK")
A14: =IFERROR(__xludf.DUMMYFUNCTION("""COMPUTED_VALUE"""),"fuHTMk6rTkU") | B14: =IFERROR(__xludf.DUMMYFUNCTION("""COMPUTED_VALUE"""),"7. ¿Cómo tramitar tu CUD?") | C14: =IFERROR(__xludf.DUMMYFUNCTION("""COMPUTED_VALUE"""),90.0) | D14: =IFERROR(__xludf.DUMMYFUNCTION("""COMPUTED_VALUE"""),"Guía de Información 2018/2019 | Certificado Único de Discapacidad - CUD") | E14: =IFERROR(__xludf.DUMMYFUNCTION("""COMPUTED_VALUE"""),"CUD") | F14: =IFERROR(__xludf.DUMMYFUNCTION("""COMPUTED_VALUE"""),"DSC_0740 CUD tramite1si.MOV") | G14: =IFERROR(__xludf.DUMMYFUNCTION("""COMPUTED_VALUE"""),93.09) | H14: =IFERROR(__xludf.DUMMYFUNCTION("""COMPUTED_VALUE"""),"CUD") | I14: =IFERROR(__xludf.DUMMYFUNCTION("""COMPUTED_VALUE"""),FALSE) | J14: =IFERROR(__xludf.DUMMYFUNCTION("""COMPUTED_VALUE"""),0.967) | K14: =IFERROR(__xludf.DUMMYFUNCTION("""COMPUTED_VALUE"""),0.0) | L14: =IFERROR(__xludf.DUMMYFUNCTION("""COMPUTED_VALUE"""),0.438) | M14: =IFERROR(__xludf.DUMMYFUNCTION("""COMPUTED_VALUE"""),"OK")
A15: =IFERROR(__xludf.DUMMYFUNCTION("""COMPUTED_VALUE"""),"6lWq6bCXwTY") | B15: =IFERROR(__xludf.DUMMYFUNCTION("""COMPUTED_VALUE"""),"8. ¿Que podes hacer si perdiste o te robaron el CUD?") | C15: =IFERROR(__xludf.DUMMYFUNCTION("""COMPUTED_VALUE"""),58.0) | D15: =IFERROR(__xludf.DUMMYFUNCTION("""COMPUTED_VALUE"""),"Guía de Información 2018/2019 | Certificado Único de Discapacidad - CUD") | E15: =IFERROR(__xludf.DUMMYFUNCTION("""COMPUTED_VALUE"""),"CUD") | F15: =IFERROR(__xludf.DUMMYFUNCTION("""COMPUTED_VALUE"""),"DSC_0746 CUD pierde si.MOV") | G15: =IFERROR(__xludf.DUMMYFUNCTION("""COMPUTED_VALUE"""),60.76) | H15: =IFERROR(__xludf.DUMMYFUNCTION("""COMPUTED_VALUE"""),"CUD") | I15: =IFERROR(__xludf.DUMMYFUNCTION("""COMPUTED_VALUE"""),FALSE) | J15: =IFERROR(__xludf.DUMMYFUNCTION("""COMPUTED_VALUE"""),0.964) | K15: =IFERROR(__xludf.DUMMYFUNCTION("""COMPUTED_VALUE"""),0.0) | L15: =IFERROR(__xludf.DUMMYFUNCTION("""COMPUTED_VALUE"""),0.337) | M15: =IFERROR(__xludf.DUMMYFUNCTION("""COMPUTED_VALUE"""),"OK")
A16: =IFERROR(__xludf.DUMMYFUNCTION("""COMPUTED_VALUE"""),"wSd8jKV42Y8") | B16: =IFERROR(__xludf.DUMMYFUNCTION("""COMPUTED_VALUE"""),"1. Apoyos Educación") | C16: =IFERROR(__xludf.DUMMYFUNCTION("""COMPUTED_VALUE"""),40.0) | D16: =IFERROR(__xludf.DUMMYFUNCTION("""COMPUTED_VALUE"""),"Guía de Información 2018/2019 | Educación") | E16: =IFERROR(__xludf.DUMMYFUNCTION("""COMPUTED_VALUE"""),"Educacion") | F16: =IFERROR(__xludf.DUMMYFUNCTION("""COMPUTED_VALUE"""),"DSC_0862 p. 85 apoyos copidis educacion.MOV") | G16: =IFERROR(__xludf.DUMMYFUNCTION("""COMPUTED_VALUE"""),50.65) | H16: =IFERROR(__xludf.DUMMYFUNCTION("""COMPUTED_VALUE"""),"Educacion") | I16: =IFERROR(__xludf.DUMMYFUNCTION("""COMPUTED_VALUE"""),TRUE) | J16: =IFERROR(__xludf.DUMMYFUNCTION("""COMPUTED_VALUE"""),0.79) | K16: =IFERROR(__xludf.DUMMYFUNCTION("""COMPUTED_VALUE"""),0.179) | L16: =IFERROR(__xludf.DUMMYFUNCTION("""COMPUTED_VALUE"""),0.475) | M16: =IFERROR(__xludf.DUMMYFUNCTION("""COMPUTED_VALUE"""),"OK")
A17: =IFERROR(__xludf.DUMMYFUNCTION("""COMPUTED_VALUE"""),"S2KHEqDAia0") | B17: =IFERROR(__xludf.DUMMYFUNCTION("""COMPUTED_VALUE"""),"2. Materia didáctico Braille ↓") | C17: =IFERROR(__xludf.DUMMYFUNCTION("""COMPUTED_VALUE"""),46.0) | D17: =IFERROR(__xludf.DUMMYFUNCTION("""COMPUTED_VALUE"""),"Guía de Información 2018/2019 | Educación") | E17: =IFERROR(__xludf.DUMMYFUNCTION("""COMPUTED_VALUE"""),"Educacion") | F17: =IFERROR(__xludf.DUMMYFUNCTION("""COMPUTED_VALUE"""),"DSC_0866 p.85 libros escolares accesibles.MOV") | G17: =IFERROR(__xludf.DUMMYFUNCTION("""COMPUTED_VALUE"""),48.15) | H17: =IFERROR(__xludf.DUMMYFUNCTION("""COMPUTED_VALUE"""),"Educacion") | I17: =IFERROR(__xludf.DUMMYFUNCTION("""COMPUTED_VALUE"""),TRUE) | J17: =IFERROR(__xludf.DUMMYFUNCTION("""COMPUTED_VALUE"""),0.955) | K17: =IFERROR(__xludf.DUMMYFUNCTION("""COMPUTED_VALUE"""),0.208) | L17: =IFERROR(__xludf.DUMMYFUNCTION("""COMPUTED_VALUE"""),0.549) | M17: =IFERROR(__xludf.DUMMYFUNCTION("""COMPUTED_VALUE"""),"OK")
A18: =IFERROR(__xludf.DUMMYFUNCTION("""COMPUTED_VALUE"""),"Psy8y4VfJ2s") | B18: =IFERROR(__xludf.DUMMYFUNCTION("""COMPUTED_VALUE"""),"3. Registro Acompañantes No Docentes APND") | C18: =IFERROR(__xludf.DUMMYFUNCTION("""COMPUTED_VALUE"""),57.0) | D18: =IFERROR(__xludf.DUMMYFUNCTION("""COMPUTED_VALUE"""),"Guía de Información 2018/2019 | Educación") | E18: =IFERROR(__xludf.DUMMYFUNCTION("""COMPUTED_VALUE"""),"Educacion") | F18: =IFERROR(__xludf.DUMMYFUNCTION("""COMPUTED_VALUE"""),"DSC_0871 p.86 registro docentes apoyo.MOV") | G18: =IFERROR(__xludf.DUMMYFUNCTION("""COMPUTED_VALUE"""),67.67) | H18: =IFERROR(__xludf.DUMMYFUNCTION("""COMPUTED_VALUE"""),"Educacion") | I18: =IFERROR(__xludf.DUMMYFUNCTION("""COMPUTED_VALUE"""),TRUE) | J18: =IFERROR(__xludf.DUMMYFUNCTION("""COMPUTED_VALUE"""),0.975) | K18: =IFERROR(__xludf.DUMMYFUNCTION("""COMPUTED_VALUE"""),0.0) | L18: =IFERROR(__xludf.DUMMYFUNCTION("""COMPUTED_VALUE"""),0.341) | M18: =IFERROR(__xludf.DUMMYFUNCTION("""COMPUTED_VALUE"""),"OK")
A19: =IFERROR(__xludf.DUMMYFUNCTION("""COMPUTED_VALUE"""),"5J9xY8gOdUY") | B19: =IFERROR(__xludf.DUMMYFUNCTION("""COMPUTED_VALUE"""),"4. Apoyos Ministerio de Educación") | C19: =IFERROR(__xludf.DUMMYFUNCTION("""COMPUTED_VALUE"""),37.0) | D19: =IFERROR(__xludf.DUMMYFUNCTION("""COMPUTED_VALUE"""),"Guía de Información 2018/2019 | Educación") | E19: =IFERROR(__xludf.DUMMYFUNCTION("""COMPUTED_VALUE"""),"Educacion") | F19: =IFERROR(__xludf.DUMMYFUNCTION("""COMPUTED_VALUE"""),"DSC_0873 p.87 que apoyos te da el Ministerio de Educacion.MOV") | G19: =IFERROR(__xludf.DUMMYFUNCTION("""COMPUTED_VALUE"""),40.14) | H19: =IFERROR(__xludf.DUMMYFUNCTION("""COMPUTED_VALUE"""),"Educacion") | I19: =IFERROR(__xludf.DUMMYFUNCTION("""COMPUTED_VALUE"""),TRUE) | J19: =IFERROR(__xludf.DUMMYFUNCTION("""COMPUTED_VALUE"""),0.922) | K19: =IFERROR(__xludf.DUMMYFUNCTION("""COMPUTED_VALUE"""),0.136) | L19: =IFERROR(__xludf.DUMMYFUNCTION("""COMPUTED_VALUE"""),0.497) | M19: =IFERROR(__xludf.DUMMYFUNCTION("""COMPUTED_VALUE"""),"OK")
A20: =IFERROR(__xludf.DUMMYFUNCTION("""COMPUTED_VALUE"""),"ihpijvrFcbY") | B20: =IFERROR(__xludf.DUMMYFUNCTION("""COMPUTED_VALUE"""),"5. Centros educativos de atención y prevención de primera infancia - CEPAPI ↓") | C20: =IFERROR(__xludf.DUMMYFUNCTION("""COMPUTED_VALUE"""),37.0) | D20: =IFERROR(__xludf.DUMMYFUNCTION("""COMPUTED_VALUE"""),"Guía de Información 2018/2019 | Educación") | E20: =IFERROR(__xludf.DUMMYFUNCTION("""COMPUTED_VALUE"""),"Educacion") | F20: =IFERROR(__xludf.DUMMYFUNCTION("""COMPUTED_VALUE"""),"DSC_0875 p.92 cepapi _ rehacer.MOV") | G20: =IFERROR(__xludf.DUMMYFUNCTION("""COMPUTED_VALUE"""),41.34) | H20: =IFERROR(__xludf.DUMMYFUNCTION("""COMPUTED_VALUE"""),"Educacion") | I20: =IFERROR(__xludf.DUMMYFUNCTION("""COMPUTED_VALUE"""),FALSE) | J20: =IFERROR(__xludf.DUMMYFUNCTION("""COMPUTED_VALUE"""),0.895) | K20: =IFERROR(__xludf.DUMMYFUNCTION("""COMPUTED_VALUE"""),0.0) | L20: =IFERROR(__xludf.DUMMYFUNCTION("""COMPUTED_VALUE"""),0.413) | M20: =IFERROR(__xludf.DUMMYFUNCTION("""COMPUTED_VALUE"""),"OK")
A21: =IFERROR(__xludf.DUMMYFUNCTION("""COMPUTED_VALUE"""),"QlS5zsPqw3k") | B21: =IFERROR(__xludf.DUMMYFUNCTION("""COMPUTED_VALUE"""),"6. Escuela hospitalaria o domiciliaria") | C21: =IFERROR(__xludf.DUMMYFUNCTION("""COMPUTED_VALUE"""),27.0) | D21: =IFERROR(__xludf.DUMMYFUNCTION("""COMPUTED_VALUE"""),"Guía de Información 2018/2019 | Educación") | E21: =IFERROR(__xludf.DUMMYFUNCTION("""COMPUTED_VALUE"""),"Educacion") | F21: =IFERROR(__xludf.DUMMYFUNCTION("""COMPUTED_VALUE"""),"DSC_0878 p. 95 escuelas hospitalarias.MOV") | G21: =IFERROR(__xludf.DUMMYFUNCTION("""COMPUTED_VALUE"""),30.63) | H21: =IFERROR(__xludf.DUMMYFUNCTION("""COMPUTED_VALUE"""),"Educacion") | I21: =IFERROR(__xludf.DUMMYFUNCTION("""COMPUTED_VALUE"""),TRUE) | J21: =IFERROR(__xludf.DUMMYFUNCTION("""COMPUTED_VALUE"""),0.947) | K21: =IFERROR(__xludf.DUMMYFUNCTION("""COMPUTED_VALUE"""),0.013) | L21: =IFERROR(__xludf.DUMMYFUNCTION("""COMPUTED_VALUE"""),0.439) | M21: =IFERROR(__xludf.DUMMYFUNCTION("""COMPUTED_VALUE"""),"OK")
A22: =IFERROR(__xludf.DUMMYFUNCTION("""COMPUTED_VALUE"""),"Wns-CUyyQL0") | B22: =IFERROR(__xludf.DUMMYFUNCTION("""COMPUTED_VALUE"""),"7. Materiales didácticos") | C22: =IFERROR(__xludf.DUMMYFUNCTION("""COMPUTED_VALUE"""),29.0) | D22: =IFERROR(__xludf.DUMMYFUNCTION("""COMPUTED_VALUE"""),"Guía de Información 2018/2019 | Educación") | E22: =IFERROR(__xludf.DUMMYFUNCTION("""COMPUTED_VALUE"""),"Educacion") | F22: =IFERROR(__xludf.DUMMYFUNCTION("""COMPUTED_VALUE"""),"DSC_0881 p.96 material en braille.MOV") | G22: =IFERROR(__xludf.DUMMYFUNCTION("""COMPUTED_VALUE"""),47.55) | H22: =IFERROR(__xludf.DUMMYFUNCTION("""COMPUTED_VALUE"""),"Educacion") | I22: =IFERROR(__xludf.DUMMYFUNCTION("""COMPUTED_VALUE"""),TRUE) | J22: =IFERROR(__xludf.DUMMYFUNCTION("""COMPUTED_VALUE"""),0.834) | K22: =IFERROR(__xludf.DUMMYFUNCTION("""COMPUTED_VALUE"""),0.0) | L22: =IFERROR(__xludf.DUMMYFUNCTION("""COMPUTED_VALUE"""),0.392) | M22: =IFERROR(__xludf.DUMMYFUNCTION("""COMPUTED_VALUE"""),"OK")
A23: =IFERROR(__xludf.DUMMYFUNCTION("""COMPUTED_VALUE"""),"bw6hm44CRQk") | B23: =IFERROR(__xludf.DUMMYFUNCTION("""COMPUTED_VALUE"""),"1. Prestaciones básicas de salud") | C23: =IFERROR(__xludf.DUMMYFUNCTION("""COMPUTED_VALUE"""),15.0) | D23: =IFERROR(__xludf.DUMMYFUNCTION("""COMPUTED_VALUE"""),"Guía de Información 2018/2019 | Salud") | E23: =IFERROR(__xludf.DUMMYFUNCTION("""COMPUTED_VALUE"""),"Salud") | F23: =IFERROR(__xludf.DUMMYFUNCTION("""COMPUTED_VALUE"""),"DSC_0726 salud2 si.MOV") | G23: =IFERROR(__xludf.DUMMYFUNCTION("""COMPUTED_VALUE"""),20.12) | H23: =IFERROR(__xludf.DUMMYFUNCTION("""COMPUTED_VALUE"""),"Salud") | I23: =IFERROR(__xludf.DUMMYFUNCTION("""COMPUTED_VALUE"""),FALSE) | J23: =IFERROR(__xludf.DUMMYFUNCTION("""COMPUTED_VALUE"""),0.875) | K23: =IFERROR(__xludf.DUMMYFUNCTION("""COMPUTED_VALUE"""),0.0) | L23: =IFERROR(__xludf.DUMMYFUNCTION("""COMPUTED_VALUE"""),0.406) | M23: =IFERROR(__xludf.DUMMYFUNCTION("""COMPUTED_VALUE"""),"OK")
A24: =IFERROR(__xludf.DUMMYFUNCTION("""COMPUTED_VALUE"""),"Vil9KHTo8p8") | B24: =IFERROR(__xludf.DUMMYFUNCTION("""COMPUTED_VALUE"""),"2. Qué son las prestaciones básicas de salud") | C24: =IFERROR(__xludf.DUMMYFUNCTION("""COMPUTED_VALUE"""),32.0) | D24: =IFERROR(__xludf.DUMMYFUNCTION("""COMPUTED_VALUE"""),"Guía de Información 2018/2019 | Salud") | E24: =IFERROR(__xludf.DUMMYFUNCTION("""COMPUTED_VALUE"""),"Salud") | F24: =IFERROR(__xludf.DUMMYFUNCTION("""COMPUTED_VALUE"""),"DSC_0789 Serv Salud basico si.MOV") | G24: =IFERROR(__xludf.DUMMYFUNCTION("""COMPUTED_VALUE"""),33.13) | H24: =IFERROR(__xludf.DUMMYFUNCTION("""COMPUTED_VALUE"""),"Salud") | I24: =IFERROR(__xludf.DUMMYFUNCTION("""COMPUTED_VALUE"""),FALSE) | J24: =IFERROR(__xludf.DUMMYFUNCTION("""COMPUTED_VALUE"""),0.974) | K24: =IFERROR(__xludf.DUMMYFUNCTION("""COMPUTED_VALUE"""),0.016) | L24: =IFERROR(__xludf.DUMMYFUNCTION("""COMPUTED_VALUE"""),0.45) | M24: =IFERROR(__xludf.DUMMYFUNCTION("""COMPUTED_VALUE"""),"OK")
A25: =IFERROR(__xludf.DUMMYFUNCTION("""COMPUTED_VALUE"""),"jomsMKgYkyQ") | B25: =IFERROR(__xludf.DUMMYFUNCTION("""COMPUTED_VALUE"""),"3. Pedir prestaciones básicas de salud") | C25: =IFERROR(__xludf.DUMMYFUNCTION("""COMPUTED_VALUE"""),37.0) | D25: =IFERROR(__xludf.DUMMYFUNCTION("""COMPUTED_VALUE"""),"Guía de Información 2018/2019 | Salud") | E25: =IFERROR(__xludf.DUMMYFUNCTION("""COMPUTED_VALUE"""),"Salud") | F25: =IFERROR(__xludf.DUMMYFUNCTION("""COMPUTED_VALUE"""),"DSC_0792 Serv Salud basico si") | H25: =IFERROR(__xludf.DUMMYFUNCTION("""COMPUTED_VALUE"""),"Salud") | M25: =IFERROR(__xludf.DUMMYFUNCTION("""COMPUTED_VALUE"""),"OK")
A26: =IFERROR(__xludf.DUMMYFUNCTION("""COMPUTED_VALUE"""),"AU3OdF0iNv0") | B26: =IFERROR(__xludf.DUMMYFUNCTION("""COMPUTED_VALUE"""),"5. Cobertura Porteña Salud") | C26: =IFERROR(__xludf.DUMMYFUNCTION("""COMPUTED_VALUE"""),34.0) | D26: =IFERROR(__xludf.DUMMYFUNCTION("""COMPUTED_VALUE"""),"Guía de Información 2018/2019 | Salud") | E26: =IFERROR(__xludf.DUMMYFUNCTION("""COMPUTED_VALUE"""),"Salud") | F26: =IFERROR(__xludf.DUMMYFUNCTION("""COMPUTED_VALUE"""),"DSC_0797 Plan Salud Ciudad si.MOV") | G26: =IFERROR(__xludf.DUMMYFUNCTION("""COMPUTED_VALUE"""),38.14) | H26: =IFERROR(__xludf.DUMMYFUNCTION("""COMPUTED_VALUE"""),"Salud") | I26: =IFERROR(__xludf.DUMMYFUNCTION("""COMPUTED_VALUE"""),TRUE) | J26: =IFERROR(__xludf.DUMMYFUNCTION("""COMPUTED_VALUE"""),0.97) | K26: =IFERROR(__xludf.DUMMYFUNCTION("""COMPUTED_VALUE"""),0.008) | L26: =IFERROR(__xludf.DUMMYFUNCTION("""COMPUTED_VALUE"""),0.444) | M26: =IFERROR(__xludf.DUMMYFUNCTION("""COMPUTED_VALUE"""),"OK")
A27: =IFERROR(__xludf.DUMMYFUNCTION("""COMPUTED_VALUE"""),"XxDsNzglSzU") | B27: =IFERROR(__xludf.DUMMYFUNCTION("""COMPUTED_VALUE"""),"6. Incluir Salud") | C27: =IFERROR(__xludf.DUMMYFUNCTION("""COMPUTED_VALUE"""),23.0) | D27: =IFERROR(__xludf.DUMMYFUNCTION("""COMPUTED_VALUE"""),"Guía de Información 2018/2019 | Salud") | E27: =IFERROR(__xludf.DUMMYFUNCTION("""COMPUTED_VALUE"""),"Salud") | F27: =IFERROR(__xludf.DUMMYFUNCTION("""COMPUTED_VALUE"""),"DSC_0798 Incluir Salud que es si.MOV") | G27: =IFERROR(__xludf.DUMMYFUNCTION("""COMPUTED_VALUE"""),36.34) | H27: =IFERROR(__xludf.DUMMYFUNCTION("""COMPUTED_VALUE"""),"Salud") | I27: =IFERROR(__xludf.DUMMYFUNCTION("""COMPUTED_VALUE"""),TRUE) | J27: =IFERROR(__xludf.DUMMYFUNCTION("""COMPUTED_VALUE"""),0.881) | K27: =IFERROR(__xludf.DUMMYFUNCTION("""COMPUTED_VALUE"""),0.101) | L27: =IFERROR(__xludf.DUMMYFUNCTION("""COMPUTED_VALUE"""),0.464) | M27: =IFERROR(__xludf.DUMMYFUNCTION("""COMPUTED_VALUE"""),"OK")
A28: =IFERROR(__xludf.DUMMYFUNCTION("""COMPUTED_VALUE"""),"jcWSZirq1ho") | B28: =IFERROR(__xludf.DUMMYFUNCTION("""COMPUTED_VALUE"""),"7. Afiliarse a Incluir Salud") | C28: =IFERROR(__xludf.DUMMYFUNCTION("""COMPUTED_VALUE"""),49.0) | D28: =IFERROR(__xludf.DUMMYFUNCTION("""COMPUTED_VALUE"""),"Guía de Información 2018/2019 | Salud") | E28: =IFERROR(__xludf.DUMMYFUNCTION("""COMPUTED_VALUE"""),"Salud") | F28: =IFERROR(__xludf.DUMMYFUNCTION("""COMPUTED_VALUE"""),"DSC_0799 Incluir Salud tramite si.MOV") | G28: =IFERROR(__xludf.DUMMYFUNCTION("""COMPUTED_VALUE"""),51.85) | H28: =IFERROR(__xludf.DUMMYFUNCTION("""COMPUTED_VALUE"""),"CUD") | I28: =IFERROR(__xludf.DUMMYFUNCTION("""COMPUTED_VALUE"""),TRUE) | J28: =IFERROR(__xludf.DUMMYFUNCTION("""COMPUTED_VALUE"""),0.945) | K28: =IFERROR(__xludf.DUMMYFUNCTION("""COMPUTED_VALUE"""),0.189) | L28: =IFERROR(__xludf.DUMMYFUNCTION("""COMPUTED_VALUE"""),0.435) | M28: =IFERROR(__xludf.DUMMYFUNCTION("""COMPUTED_VALUE"""),"OK")
A29: =IFERROR(__xludf.DUMMYFUNCTION("""COMPUTED_VALUE"""),"u07hL-EzTpY") | B29: =IFERROR(__xludf.DUMMYFUNCTION("""COMPUTED_VALUE"""),"1. Programa Hogares") | C29: =IFERROR(__xludf.DUMMYFUNCTION("""COMPUTED_VALUE"""),52.0) | D29: =IFERROR(__xludf.DUMMYFUNCTION("""COMPUTED_VALUE"""),"Guia de Información 2018/2019 | Servicios Sociales Zonales") | E29: =IFERROR(__xludf.DUMMYFUNCTION("""COMPUTED_VALUE"""),"SSZonales") | F29: =IFERROR(__xludf.DUMMYFUNCTION("""COMPUTED_VALUE"""),"DSC_0851 p.73.MOV") | G29: =IFERROR(__xludf.DUMMYFUNCTION("""COMPUTED_VALUE"""),55.66) | H29: =IFERROR(__xludf.DUMMYFUNCTION("""COMPUTED_VALUE"""),"Accesibilidad") | I29: =IFERROR(__xludf.DUMMYFUNCTION("""COMPUTED_VALUE"""),TRUE) | J29: =IFERROR(__xludf.DUMMYFUNCTION("""COMPUTED_VALUE"""),0.934) | K29: =IFERROR(__xludf.DUMMYFUNCTION("""COMPUTED_VALUE"""),0.13) | L29: =IFERROR(__xludf.DUMMYFUNCTION("""COMPUTED_VALUE"""),0.399) | M29: =IFERROR(__xludf.DUMMYFUNCTION("""COMPUTED_VALUE"""),"OK")
A30: =IFERROR(__xludf.DUMMYFUNCTION("""COMPUTED_VALUE"""),"T_vgQJhMWf8") | B30: =IFERROR(__xludf.DUMMYFUNCTION("""COMPUTED_VALUE"""),"2. Apoyos del Gobierno de la Nación") | C30: =IFERROR(__xludf.DUMMYFUNCTION("""COMPUTED_VALUE"""),44.0) | D30: =IFERROR(__xludf.DUMMYFUNCTION("""COMPUTED_VALUE"""),"Guia de Información 2018/2019 | Servicios Sociales Zonales") | E30: =IFERROR(__xludf.DUMMYFUNCTION("""COMPUTED_VALUE"""),"SSZonales") | F30: =IFERROR(__xludf.DUMMYFUNCTION("""COMPUTED_VALUE"""),"DSC_0856 p.74.MOV") | G30: =IFERROR(__xludf.DUMMYFUNCTION("""COMPUTED_VALUE"""),51.25) | H30: =IFERROR(__xludf.DUMMYFUNCTION("""COMPUTED_VALUE"""),"Accesibilidad") | I30: =IFERROR(__xludf.DUMMYFUNCTION("""COMPUTED_VALUE"""),TRUE) | J30: =IFERROR(__xludf.DUMMYFUNCTION("""COMPUTED_VALUE"""),0.859) | K30: =IFERROR(__xludf.DUMMYFUNCTION("""COMPUTED_VALUE"""),0.108) | L30: =IFERROR(__xludf.DUMMYFUNCTION("""COMPUTED_VALUE"""),0.36) | M30: =IFERROR(__xludf.DUMMYFUNCTION("""COMPUTED_VALUE"""),"OK")
A31: =IFERROR(__xludf.DUMMYFUNCTION("""COMPUTED_VALUE"""),"2iYRa7hKg2g") | B31: =IFERROR(__xludf.DUMMYFUNCTION("""COMPUTED_VALUE"""),"3. Pedir ayuda técnica") | C31: =IFERROR(__xludf.DUMMYFUNCTION("""COMPUTED_VALUE"""),31.0) | D31: =IFERROR(__xludf.DUMMYFUNCTION("""COMPUTED_VALUE"""),"Guia de Información 2018/2019 | Servicios Sociales Zonales") | E31: =IFERROR(__xludf.DUMMYFUNCTION("""COMPUTED_VALUE"""),"SSZonales") | F31: =IFERROR(__xludf.DUMMYFUNCTION("""COMPUTED_VALUE"""),"DSC_0858 p. 75 ayuda tecnica.MOV") | G31: =IFERROR(__xludf.DUMMYFUNCTION("""COMPUTED_VALUE"""),45.05) | H31: =IFERROR(__xludf.DUMMYFUNCTION("""COMPUTED_VALUE"""),"Accesibilidad") | I31: =IFERROR(__xludf.DUMMYFUNCTION("""COMPUTED_VALUE"""),TRUE) | J31: =IFERROR(__xludf.DUMMYFUNCTION("""COMPUTED_VALUE"""),0.688) | K31: =IFERROR(__xludf.DUMMYFUNCTION("""COMPUTED_VALUE"""),0.231) | L31: =IFERROR(__xludf.DUMMYFUNCTION("""COMPUTED_VALUE"""),0.368) | M31: =IFERROR(__xludf.DUMMYFUNCTION("""COMPUTED_VALUE"""),"OK")
A32: =IFERROR(__xludf.DUMMYFUNCTION("""COMPUTED_VALUE"""),"KrAliLan0Gs") | B32: =IFERROR(__xludf.DUMMYFUNCTION("""COMPUTED_VALUE"""),"1. Sistema previsional") | C32: =IFERROR(__xludf.DUMMYFUNCTION("""COMPUTED_VALUE"""),50.0) | D32: =IFERROR(__xludf.DUMMYFUNCTION("""COMPUTED_VALUE"""),"Guía de Información 2018/2019 | Sistema Previsional") | E32: =IFERROR(__xludf.DUMMYFUNCTION("""COMPUTED_VALUE"""),"Prestaciones") | F32: =IFERROR(__xludf.DUMMYFUNCTION("""COMPUTED_VALUE"""),"DSC_0701 Titulo Sistema Prev.MOV") | G32: =IFERROR(__xludf.DUMMYFUNCTION("""COMPUTED_VALUE"""),14.11) | H32: =IFERROR(__xludf.DUMMYFUNCTION("""COMPUTED_VALUE"""),"unknown") | I32: =IFERROR(__xludf.DUMMYFUNCTION("""COMPUTED_VALUE"""),FALSE) | J32: =IFERROR(__xludf.DUMMYFUNCTION("""COMPUTED_VALUE"""),0.992) | K32: =IFERROR(__xludf.DUMMYFUNCTION("""COMPUTED_VALUE"""),0.0) | L32: =IFERROR(__xludf.DUMMYFUNCTION("""COMPUTED_VALUE"""),0.347) | M32: =IFERROR(__xludf.DUMMYFUNCTION("""COMPUTED_VALUE"""),"OK")
A33: =IFERROR(__xludf.DUMMYFUNCTION("""COMPUTED_VALUE"""),"DpT8rj_OyXI") | B33: =IFERROR(__xludf.DUMMYFUNCTION("""COMPUTED_VALUE"""),"10. Edad jubilación por discapacidad") | C33: =IFERROR(__xludf.DUMMYFUNCTION("""COMPUTED_VALUE"""),21.0) | D33: =IFERROR(__xludf.DUMMYFUNCTION("""COMPUTED_VALUE"""),"Guía de Información 2018/2019 | Sistema Previsional") | E33: =IFERROR(__xludf.DUMMYFUNCTION("""COMPUTED_VALUE"""),"Prestaciones") | F33: =IFERROR(__xludf.DUMMYFUNCTION("""COMPUTED_VALUE"""),"DSC_0780 Jubil disc edad si.MOV") | G33: =IFERROR(__xludf.DUMMYFUNCTION("""COMPUTED_VALUE"""),22.62) | H33: =IFERROR(__xludf.DUMMYFUNCTION("""COMPUTED_VALUE"""),"Prestaciones") | I33: =IFERROR(__xludf.DUMMYFUNCTION("""COMPUTED_VALUE"""),FALSE) | J33: =IFERROR(__xludf.DUMMYFUNCTION("""COMPUTED_VALUE"""),0.973) | K33: =IFERROR(__xludf.DUMMYFUNCTION("""COMPUTED_VALUE"""),0.0) | L33: =IFERROR(__xludf.DUMMYFUNCTION("""COMPUTED_VALUE"""),0.441) | M33: =IFERROR(__xludf.DUMMYFUNCTION("""COMPUTED_VALUE"""),"OK")
A34: =IFERROR(__xludf.DUMMYFUNCTION("""COMPUTED_VALUE"""),"hHqyvAOZpwk") | B34: =IFERROR(__xludf.DUMMYFUNCTION("""COMPUTED_VALUE"""),"11. Retiro por invalidez") | C34: =IFERROR(__xludf.DUMMYFUNCTION("""COMPUTED_VALUE"""),33.0) | D34: =IFERROR(__xludf.DUMMYFUNCTION("""COMPUTED_VALUE"""),"Guía de Información 2018/2019 | Sistema Previsional") | E34: =IFERROR(__xludf.DUMMYFUNCTION("""COMPUTED_VALUE"""),"Prestaciones") | F34: =IFERROR(__xludf.DUMMYFUNCTION("""COMPUTED_VALUE"""),"DSC_0785 Retiro si.MOV") | G34: =IFERROR(__xludf.DUMMYFUNCTION("""COMPUTED_VALUE"""),34.53) | H34: =IFERROR(__xludf.DUMMYFUNCTION("""COMPUTED_VALUE"""),"Prestaciones") | I34: =IFERROR(__xludf.DUMMYFUNCTION("""COMPUTED_VALUE"""),FALSE) | J34: =IFERROR(__xludf.DUMMYFUNCTION("""COMPUTED_VALUE"""),0.985) | K34: =IFERROR(__xludf.DUMMYFUNCTION("""COMPUTED_VALUE"""),0.0) | L34: =IFERROR(__xludf.DUMMYFUNCTION("""COMPUTED_VALUE"""),0.445) | M34: =IFERROR(__xludf.DUMMYFUNCTION("""COMPUTED_VALUE"""),"OK")
A35: =IFERROR(__xludf.DUMMYFUNCTION("""COMPUTED_VALUE"""),"BbiF_2145Es") | B35: =IFERROR(__xludf.DUMMYFUNCTION("""COMPUTED_VALUE"""),"2. Pensión no contributiva por discapacidad - PNC") | C35: =IFERROR(__xludf.DUMMYFUNCTION("""COMPUTED_VALUE"""),22.0) | D35: =IFERROR(__xludf.DUMMYFUNCTION("""COMPUTED_VALUE"""),"Guía de Información 2018/2019 | Sistema Previsional") | E35: =IFERROR(__xludf.DUMMYFUNCTION("""COMPUTED_VALUE"""),"Prestaciones") | F35: =IFERROR(__xludf.DUMMYFUNCTION("""COMPUTED_VALUE"""),"DSC_0749 PNC2.MOV") | G35: =IFERROR(__xludf.DUMMYFUNCTION("""COMPUTED_VALUE"""),24.12) | H35: =IFERROR(__xludf.DUMMYFUNCTION("""COMPUTED_VALUE"""),"Prestaciones") | I35: =IFERROR(__xludf.DUMMYFUNCTION("""COMPUTED_VALUE"""),FALSE) | J35: =IFERROR(__xludf.DUMMYFUNCTION("""COMPUTED_VALUE"""),0.965) | K35: =IFERROR(__xludf.DUMMYFUNCTION("""COMPUTED_VALUE"""),0.0) | L35: =IFERROR(__xludf.DUMMYFUNCTION("""COMPUTED_VALUE"""),0.438) | M35: =IFERROR(__xludf.DUMMYFUNCTION("""COMPUTED_VALUE"""),"OK")
A36: =IFERROR(__xludf.DUMMYFUNCTION("""COMPUTED_VALUE"""),"DpT8rj_OyXI") | B36: =IFERROR(__xludf.DUMMYFUNCTION("""COMPUTED_VALUE"""),"4. ¿Cómo se tramita la pensión por discapacidad?") | C36: =IFERROR(__xludf.DUMMYFUNCTION("""COMPUTED_VALUE"""),14.0) | D36: =IFERROR(__xludf.DUMMYFUNCTION("""COMPUTED_VALUE"""),"Guía de Información 2018/2019 | Sistema Previsional") | E36: =IFERROR(__xludf.DUMMYFUNCTION("""COMPUTED_VALUE"""),"Prestaciones") | F36: =IFERROR(__xludf.DUMMYFUNCTION("""COMPUTED_VALUE"""),"DSC_0761 PNC dnd si.MOV") | G36: =IFERROR(__xludf.DUMMYFUNCTION("""COMPUTED_VALUE"""),23.72) | H36: =IFERROR(__xludf.DUMMYFUNCTION("""COMPUTED_VALUE"""),"Prestaciones") | I36: =IFERROR(__xludf.DUMMYFUNCTION("""COMPUTED_VALUE"""),FALSE) | J36: =IFERROR(__xludf.DUMMYFUNCTION("""COMPUTED_VALUE"""),0.885) | K36: =IFERROR(__xludf.DUMMYFUNCTION("""COMPUTED_VALUE"""),0.0) | L36: =IFERROR(__xludf.DUMMYFUNCTION("""COMPUTED_VALUE"""),0.41) | M36: =IFERROR(__xludf.DUMMYFUNCTION("""COMPUTED_VALUE"""),"OK")
A37: =IFERROR(__xludf.DUMMYFUNCTION("""COMPUTED_VALUE"""),"i1YJ2VoH6_k") | B37: =IFERROR(__xludf.DUMMYFUNCTION("""COMPUTED_VALUE"""),"5. Certificado Médico Oficial - CMO") | C37: =IFERROR(__xludf.DUMMYFUNCTION("""COMPUTED_VALUE"""),34.0) | D37: =IFERROR(__xludf.DUMMYFUNCTION("""COMPUTED_VALUE"""),"Guía de Información 2018/2019 | Sistema Previsional") | E37: =IFERROR(__xludf.DUMMYFUNCTION("""COMPUTED_VALUE"""),"Prestaciones") | F37: =IFERROR(__xludf.DUMMYFUNCTION("""COMPUTED_VALUE"""),"DSC_0765 CMO si.MOV") | G37: =IFERROR(__xludf.DUMMYFUNCTION("""COMPUTED_VALUE"""),35.34) | H37: =IFERROR(__xludf.DUMMYFUNCTION("""COMPUTED_VALUE"""),"Prestaciones") | I37: =IFERROR(__xludf.DUMMYFUNCTION("""COMPUTED_VALUE"""),FALSE) | J37: =IFERROR(__xludf.DUMMYFUNCTION("""COMPUTED_VALUE"""),0.906) | K37: =IFERROR(__xludf.DUMMYFUNCTION("""COMPUTED_VALUE"""),0.0) | L37: =IFERROR(__xludf.DUMMYFUNCTION("""COMPUTED_VALUE"""),0.417) | M37: =IFERROR(__xludf.DUMMYFUNCTION("""COMPUTED_VALUE"""),"OK")
A38: =IFERROR(__xludf.DUMMYFUNCTION("""COMPUTED_VALUE"""),"rX2VatRZzBE") | B38: =IFERROR(__xludf.DUMMYFUNCTION("""COMPUTED_VALUE"""),"7. ¿Cuándo podes cobrar la asignación por hijo con discapacidad?") | C38: =IFERROR(__xludf.DUMMYFUNCTION("""COMPUTED_VALUE"""),28.0) | D38: =IFERROR(__xludf.DUMMYFUNCTION("""COMPUTED_VALUE"""),"Guía de Información 2018/2019 | Sistema Previsional") | E38: =IFERROR(__xludf.DUMMYFUNCTION("""COMPUTED_VALUE"""),"Prestaciones") | F38: =IFERROR(__xludf.DUMMYFUNCTION("""COMPUTED_VALUE"""),"DSC_0771 AHHD si.MOV") | G38: =IFERROR(__xludf.DUMMYFUNCTION("""COMPUTED_VALUE"""),31.23) | H38: =IFERROR(__xludf.DUMMYFUNCTION("""COMPUTED_VALUE"""),"Prestaciones") | I38: =IFERROR(__xludf.DUMMYFUNCTION("""COMPUTED_VALUE"""),FALSE) | J38: =IFERROR(__xludf.DUMMYFUNCTION("""COMPUTED_VALUE"""),0.946) | K38: =IFERROR(__xludf.DUMMYFUNCTION("""COMPUTED_VALUE"""),0.0) | L38: =IFERROR(__xludf.DUMMYFUNCTION("""COMPUTED_VALUE"""),0.431) | M38: =IFERROR(__xludf.DUMMYFUNCTION("""COMPUTED_VALUE"""),"OK")
A39: =IFERROR(__xludf.DUMMYFUNCTION("""COMPUTED_VALUE"""),"V0hm94uW_to") | B39: =IFERROR(__xludf.DUMMYFUNCTION("""COMPUTED_VALUE"""),"9. Jubilación por discapacidad") | C39: =IFERROR(__xludf.DUMMYFUNCTION("""COMPUTED_VALUE"""),25.0) | D39: =IFERROR(__xludf.DUMMYFUNCTION("""COMPUTED_VALUE"""),"Guía de Información 2018/2019 | Sistema Previsional") | E39: =IFERROR(__xludf.DUMMYFUNCTION("""COMPUTED_VALUE"""),"Prestaciones") | F39: =IFERROR(__xludf.DUMMYFUNCTION("""COMPUTED_VALUE"""),"DSC_0775 Jubil disc si.MOV") | G39: =IFERROR(__xludf.DUMMYFUNCTION("""COMPUTED_VALUE"""),26.03) | H39: =IFERROR(__xludf.DUMMYFUNCTION("""COMPUTED_VALUE"""),"Prestaciones") | I39: =IFERROR(__xludf.DUMMYFUNCTION("""COMPUTED_VALUE"""),FALSE) | J39: =IFERROR(__xludf.DUMMYFUNCTION("""COMPUTED_VALUE"""),0.93) | K39: =IFERROR(__xludf.DUMMYFUNCTION("""COMPUTED_VALUE"""),0.0) | L39: =IFERROR(__xludf.DUMMYFUNCTION("""COMPUTED_VALUE"""),0.425) | M39: =IFERROR(__xludf.DUMMYFUNCTION("""COMPUTED_VALUE"""),"OK")
A40: =IFERROR(__xludf.DUMMYFUNCTION("""COMPUTED_VALUE"""),"_j3n-b6Fc_A") | B40: =IFERROR(__xludf.DUMMYFUNCTION("""COMPUTED_VALUE"""),"1. Registro Único Laboral - RUL") | C40: =IFERROR(__xludf.DUMMYFUNCTION("""COMPUTED_VALUE"""),68.0) | D40: =IFERROR(__xludf.DUMMYFUNCTION("""COMPUTED_VALUE"""),"Guía de Información 2018/2019 | Trabajo") | E40: =IFERROR(__xludf.DUMMYFUNCTION("""COMPUTED_VALUE"""),"Trabajo") | F40: =IFERROR(__xludf.DUMMYFUNCTION("""COMPUTED_VALUE"""),"DSC_0884 p.108 rul.MOV") | G40: =IFERROR(__xludf.DUMMYFUNCTION("""COMPUTED_VALUE"""),74.07) | H40: =IFERROR(__xludf.DUMMYFUNCTION("""COMPUTED_VALUE"""),"Trabajo") | I40: =IFERROR(__xludf.DUMMYFUNCTION("""COMPUTED_VALUE"""),TRUE) | J40: =IFERROR(__xludf.DUMMYFUNCTION("""COMPUTED_VALUE"""),0.918) | K40: =IFERROR(__xludf.DUMMYFUNCTION("""COMPUTED_VALUE"""),0.165) | L40: =IFERROR(__xludf.DUMMYFUNCTION("""COMPUTED_VALUE"""),0.512) | M40: =IFERROR(__xludf.DUMMYFUNCTION("""COMPUTED_VALUE"""),"OK")
...

Sheet NO_CURADOS
A1: =IFERROR(__xludf.DUMMYFUNCTION("{ MATCHES!A1:E1; SORT( UNIQUE( FILTER( MATCHES!A2:E1000, MATCHES!M2:M1000<>""OK"", ISNA( MATCH( MATCHES!A2:A1000, FILTER(MATCHES!A2:A1000, MATCHES!M2:M1000=""OK""), 0 ) ) ) "&" ), 4, TRUE, 2, TRUE ) }"),"yt_id") | B1: =IFERROR(__xludf.DUMMYFUNCTION("""COMPUTED_VALUE"""),"yt_title") | C1: =IFERROR(__xludf.DUMMYFUNCTION("""COMPUTED_VALUE"""),"yt_dur_s") | D1: =IFERROR(__xludf.DUMMYFUNCTION("""COMPUTED_VALUE"""),"playlist") | E1: =IFERROR(__xludf.DUMMYFUNCTION("""COMPUTED_VALUE"""),"yt_topic")
A2: =IFERROR(__xludf.DUMMYFUNCTION("""COMPUTED_VALUE"""),"0Vxf04VftJE") | B2: =IFERROR(__xludf.DUMMYFUNCTION("""COMPUTED_VALUE"""),"1. Beneficios fiscales") | C2: =IFERROR(__xludf.DUMMYFUNCTION("""COMPUTED_VALUE"""),5.0) | D2: =IFERROR(__xludf.DUMMYFUNCTION("""COMPUTED_VALUE"""),"Guía de Información 2018/2019 | Beneficios Fiscales") | E2: =IFERROR(__xludf.DUMMYFUNCTION("""COMPUTED_VALUE"""),"BeneficiosFiscales")
A3: =IFERROR(__xludf.DUMMYFUNCTION("""COMPUTED_VALUE"""),"vP2AvPqVYa8") | B3: =IFERROR(__xludf.DUMMYFUNCTION("""COMPUTED_VALUE"""),"2. ¿Qué es una exención fiscal?") | C3: =IFERROR(__xludf.DUMMYFUNCTION("""COMPUTED_VALUE"""),21.0) | D3: =IFERROR(__xludf.DUMMYFUNCTION("""COMPUTED_VALUE"""),"Guía de Información 2018/2019 | Beneficios Fiscales") | E3: =IFERROR(__xludf.DUMMYFUNCTION("""COMPUTED_VALUE"""),"BeneficiosFiscales")
A4: =IFERROR(__xludf.DUMMYFUNCTION("""COMPUTED_VALUE"""),"75jVq4wKLEo") | B4: =IFERROR(__xludf.DUMMYFUNCTION("""COMPUTED_VALUE"""),"5. ¿Para qué son los ajustes razonables?") | C4: =IFERROR(__xludf.DUMMYFUNCTION("""COMPUTED_VALUE"""),24.0) | D4: =IFERROR(__xludf.DUMMYFUNCTION("""COMPUTED_VALUE"""),"Guía de Información 2018/2019 | Certificado Único de Discapacidad - CUD") | E4: =IFERROR(__xludf.DUMMYFUNCTION("""COMPUTED_VALUE"""),"CUD")
A5: =IFERROR(__xludf.DUMMYFUNCTION("""COMPUTED_VALUE"""),"J6xUFDqW4BA") | B5: =IFERROR(__xludf.DUMMYFUNCTION("""COMPUTED_VALUE"""),"1. Organizaciones Sociedad Civil - OSC") | C5: =IFERROR(__xludf.DUMMYFUNCTION("""COMPUTED_VALUE"""),50.0) | D5: =IFERROR(__xludf.DUMMYFUNCTION("""COMPUTED_VALUE"""),"Guía de Información 2018/2019 | Participación") | E5: =IFERROR(__xludf.DUMMYFUNCTION("""COMPUTED_VALUE"""),"Participacion")
A6: =IFERROR(__xludf.DUMMYFUNCTION("""COMPUTED_VALUE"""),"OTmV28NGG5I") | B6: =IFERROR(__xludf.DUMMYFUNCTION("""COMPUTED_VALUE"""),"2 - Fortalecimiento ↓") | C6: =IFERROR(__xludf.DUMMYFUNCTION("""COMPUTED_VALUE"""),25.0) | D6: =IFERROR(__xludf.DUMMYFUNCTION("""COMPUTED_VALUE"""),"Guía de Información 2018/2019 | Participación") | E6: =IFERROR(__xludf.DUMMYFUNCTION("""COMPUTED_VALUE"""),"Participacion")
A7: =IFERROR(__xludf.DUMMYFUNCTION("""COMPUTED_VALUE"""),"Mu_txXs9ihg") | B7: =IFERROR(__xludf.DUMMYFUNCTION("""COMPUTED_VALUE"""),"4. Reclamar prestaciones básicas de salud") | C7: =IFERROR(__xludf.DUMMYFUNCTION("""COMPUTED_VALUE"""),63.0) | D7: =IFERROR(__xludf.DUMMYFUNCTION("""COMPUTED_VALUE"""),"Guía de Información 2018/2019 | Salud") | E7: =IFERROR(__xludf.DUMMYFUNCTION("""COMPUTED_VALUE"""),"Salud")
A8: =IFERROR(__xludf.DUMMYFUNCTION("""COMPUTED_VALUE"""),"MkSTIErbEbk") | B8: =IFERROR(__xludf.DUMMYFUNCTION("""COMPUTED_VALUE"""),"3. ¿Cuándo podes cobrar la pensión por discapacidad?") | C8: =IFERROR(__xludf.DUMMYFUNCTION("""COMPUTED_VALUE"""),39.0) | D8: =IFERROR(__xludf.DUMMYFUNCTION("""COMPUTED_VALUE"""),"Guía de Información 2018/2019 | Sistema Previsional") | E8: =IFERROR(__xludf.DUMMYFUNCTION("""COMPUTED_VALUE"""),"Prestaciones")
A9: =IFERROR(__xludf.DUMMYFUNCTION("""COMPUTED_VALUE"""),"71AmCt5zrr8") | B9: =IFERROR(__xludf.DUMMYFUNCTION("""COMPUTED_VALUE"""),"4. ¿Cómo se tramita la pensión por discapacidad?") | C9: =IFERROR(__xludf.DUMMYFUNCTION("""COMPUTED_VALUE"""),14.0) | D9: =IFERROR(__xludf.DUMMYFUNCTION("""COMPUTED_VALUE"""),"Guía de Información 2018/2019 | Sistema Previsional") | E9: =IFERROR(__xludf.DUMMYFUNCTION("""COMPUTED_VALUE"""),"Prestaciones")
A10: =IFERROR(__xludf.DUMMYFUNCTION("""COMPUTED_VALUE"""),"O_9wfdgHaW4") | B10: =IFERROR(__xludf.DUMMYFUNCTION("""COMPUTED_VALUE"""),"8. Asignación por hijo con discapacidad") | C10: =IFERROR(__xludf.DUMMYFUNCTION("""COMPUTED_VALUE"""),38.0) | D10: =IFERROR(__xludf.DUMMYFUNCTION("""COMPUTED_VALUE"""),"Guía de Información 2018/2019 | Sistema Previsional") | E10: =IFERROR(__xludf.DUMMYFUNCTION("""COMPUTED_VALUE"""),"Prestaciones")
A11: =IFERROR(__xludf.DUMMYFUNCTION("""COMPUTED_VALUE"""),"kcChz0qrXZs") | B11: =IFERROR(__xludf.DUMMYFUNCTION("""COMPUTED_VALUE"""),"5. Símbolo Internacional de Acceso") | C11: =IFERROR(__xludf.DUMMYFUNCTION("""COMPUTED_VALUE"""),66.0) | D11: =IFERROR(__xludf.DUMMYFUNCTION("""COMPUTED_VALUE"""),"Guía de Información 2018/2019 | Transporte") | E11: =IFERROR(__xludf.DUMMYFUNCTION("""COMPUTED_VALUE"""),"Transporte")
A12: =IFERROR(__xludf.DUMMYFUNCTION("""COMPUTED_VALUE"""),"ook_O5pd3D0") | B12: =IFERROR(__xludf.DUMMYFUNCTION("""COMPUTED_VALUE"""),"Circuito 1: San Nicolás / Casco Histórico") | C12: =IFERROR(__xludf.DUMMYFUNCTION("""COMPUTED_VALUE"""),222.0) | D12: =IFERROR(__xludf.DUMMYFUNCTION("""COMPUTED_VALUE"""),"Guía de Turismo 2018/2019") | E12: =IFERROR(__xludf.DUMMYFUNCTION("""COMPUTED_VALUE"""),"Turismo")
A13: =IFERROR(__xludf.DUMMYFUNCTION("""COMPUTED_VALUE"""),"VlfX8oURh-s") | B13: =IFERROR(__xludf.DUMMYFUNCTION("""COMPUTED_VALUE"""),"Circuito 2: San Telmo / La Boca") | C13: =IFERROR(__xludf.DUMMYFUNCTION("""COMPUTED_VALUE"""),276.0) | D13: =IFERROR(__xludf.DUMMYFUNCTION("""COMPUTED_VALUE"""),"Guía de Turismo 2018/2019") | E13: =IFERROR(__xludf.DUMMYFUNCTION("""COMPUTED_VALUE"""),"Turismo")
A14: =IFERROR(__xludf.DUMMYFUNCTION("""COMPUTED_VALUE"""),"q4S4J59Dvr8") | B14: =IFERROR(__xludf.DUMMYFUNCTION("""COMPUTED_VALUE"""),"Circuito 3: Recoleta / Retiro") | C14: =IFERROR(__xludf.DUMMYFUNCTION("""COMPUTED_VALUE"""),190.0) | D14: =IFERROR(__xludf.DUMMYFUNCTION("""COMPUTED_VALUE"""),"Guía de Turismo 2018/2019") | E14: =IFERROR(__xludf.DUMMYFUNCTION("""COMPUTED_VALUE"""),"Turismo")
A15: =IFERROR(__xludf.DUMMYFUNCTION("""COMPUTED_VALUE"""),"nbHsyDeo3Eo") | B15: =IFERROR(__xludf.DUMMYFUNCTION("""COMPUTED_VALUE"""),"Circuito 4: Puerto Madero / Balvanera") | C15: =IFERROR(__xludf.DUMMYFUNCTION("""COMPUTED_VALUE"""),270.0) | D15: =IFERROR(__xludf.DUMMYFUNCTION("""COMPUTED_VALUE"""),"Guía de Turismo 2018/2019") | E15: =IFERROR(__xludf.DUMMYFUNCTION("""COMPUTED_VALUE"""),"Turismo")
A16: =IFERROR(__xludf.DUMMYFUNCTION("""COMPUTED_VALUE"""),"QG7ND5YNfVQ") | B16: =IFERROR(__xludf.DUMMYFUNCTION("""COMPUTED_VALUE"""),"Circuito 5: Palermo / Belgrano") | C16: =IFERROR(__xludf.DUMMYFUNCTION("""COMPUTED_VALUE"""),196.0) | D16: =IFERROR(__xludf.DUMMYFUNCTION("""COMPUTED_VALUE"""),"Guía de Turismo 2018/2019") | E16: =IFERROR(__xludf.DUMMYFUNCTION("""COMPUTED_VALUE"""),"Turismo")
A17: =IFERROR(__xludf.DUMMYFUNCTION("""COMPUTED_VALUE"""),"7az9Z92XonA") | B17: =IFERROR(__xludf.DUMMYFUNCTION("""COMPUTED_VALUE"""),"Circuito 6: Provincia de Buenos Aires - La Plata") | C17: =IFERROR(__xludf.DUMMYFUNCTION("""COMPUTED_VALUE"""),66.0) | D17: =IFERROR(__xludf.DUMMYFUNCTION("""COMPUTED_VALUE"""),"Guía de Turismo 2018/2019") | E17: =IFERROR(__xludf.DUMMYFUNCTION("""COMPUTED_VALUE"""),"Turismo")
A18: =IFERROR(__xludf.DUMMYFUNCTION("""COMPUTED_VALUE"""),"EGxhVpFU1OI") | B18: =IFERROR(__xludf.DUMMYFUNCTION("""COMPUTED_VALUE"""),"Circuito 7: Provincia de Buenos Aires / Bahía Blanca") | C18: =IFERROR(__xludf.DUMMYFUNCTION("""COMPUTED_VALUE"""),59.0) | D18: =IFERROR(__xludf.DUMMYFUNCTION("""COMPUTED_VALUE"""),"Guía de Turismo 2018/2019") | E18: =IFERROR(__xludf.DUMMYFUNCTION("""COMPUTED_VALUE"""),"Turismo")
A19: =IFERROR(__xludf.DUMMYFUNCTION("""COMPUTED_VALUE"""),"bg8ySVMa71A") | B19: =IFERROR(__xludf.DUMMYFUNCTION("""COMPUTED_VALUE"""),"Circuito 8 y 9: Provincia de Buenos Aires/ Mar del Plata") | C19: =IFERROR(__xludf.DUMMYFUNCTION("""COMPUTED_VALUE"""),60.0) | D19: =IFERROR(__xludf.DUMMYFUNCTION("""COMPUTED_VALUE"""),"Guía de Turismo 2018/2019") | E19: =IFERROR(__xludf.DUMMYFUNCTION("""COMPUTED_VALUE"""),"Turismo")

Sheet CRUDOS
A1: num | B1: dsc_stem | C1: asignado | D1: has_subtitle
A2: 1044 | B2: DSC_1044 fortalecimiento si | C2: {=IF( COUNTIF( SUBSTITUTE(CURADOS!F$2:F1000, ".MOV", ""), SUBSTITUTE(B2, ".MOV", "") )>0, TRUE, FALSE )} | D2: TRUE
A3: 1042 | B3: DSC_1042 osc si | C3: {=IF( COUNTIF( SUBSTITUTE(CURADOS!F$2:F1000, ".MOV", ""), SUBSTITUTE(B3, ".MOV", "") )>0, TRUE, FALSE )} | D3: TRUE
A4: 1028 | B4: DSC_1028 becas ultima parte | C4: {=IF( COUNTIF( SUBSTITUTE(CURADOS!F$2:F1000, ".MOV", ""), SUBSTITUTE(B4, ".MOV", "") )>0, TRUE, FALSE )} | D4: FALSE
A5: 850 | B5: DSC_0850 p.7172 (VER) | C5: {=IF( COUNTIF( SUBSTITUTE(CURADOS!F$2:F1000, ".MOV", ""), SUBSTITUTE(B5, ".MOV", "") )>0, TRUE, FALSE )} | D5: FALSE
A6: 818 | B6: DSC_0818 Simbolo si mejor | C6: {=IF( COUNTIF( SUBSTITUTE(CURADOS!F$2:F1000, ".MOV", ""), SUBSTITUTE(B6, ".MOV", "") )>0, TRUE, FALSE )} | D6: TRUE
A7: 815 | B7: DSC_0815 Perro guia si ultima parte | C7: {=IF( COUNTIF( SUBSTITUTE(CURADOS!F$2:F1000, ".MOV", ""), SUBSTITUTE(B7, ".MOV", "") )>0, TRUE, FALSE )} | D7: FALSE
A8: 795 | B8: DSC_0795 Sin rta si | C8: {=IF( COUNTIF( SUBSTITUTE(CURADOS!F$2:F1000, ".MOV", ""), SUBSTITUTE(B8, ".MOV", "") )>0, TRUE, FALSE )} | D8: TRUE
A9: 773 | B9: DSC_0773 Pension fliar si | C9: {=IF( COUNTIF( SUBSTITUTE(CURADOS!F$2:F1000, ".MOV", ""), SUBSTITUTE(B9, ".MOV", "") )>0, TRUE, FALSE )} | D9: FALSE
A10: 771 | B10: DSC_0771 | C10: {=IF( COUNTIF( SUBSTITUTE(CURADOS!F$2:F1000, ".MOV", ""), SUBSTITUTE(B10, ".MOV", "") )>0, TRUE, FALSE )} | D10: FALSE
A11: 769 | B11: DSC_0769 (2) | C11: {=IF( COUNTIF( SUBSTITUTE(CURADOS!F$2:F1000, ".MOV", ""), SUBSTITUTE(B11, ".MOV", "") )>0, TRUE, FALSE )} | D11: FALSE
A12: 769 | B12: DSC_0769 | C12: {=IF( COUNTIF( SUBSTITUTE(CURADOS!F$2:F1000, ".MOV", ""), SUBSTITUTE(B12, ".MOV", "") )>0, TRUE, FALSE )} | D12: FALSE
A13: 768 | B13: DSC_0768 | C13: {=IF( COUNTIF( SUBSTITUTE(CURADOS!F$2:F1000, ".MOV", ""), SUBSTITUTE(B13, ".MOV", "") )>0, TRUE, FALSE )} | D13: FALSE
A14: 760 | B14: DSC_0760 PNC quien si | C14: {=IF( COUNTIF( SUBSTITUTE(CURADOS!F$2:F1000, ".MOV", ""), SUBSTITUTE(B14, ".MOV", "") )>0, TRUE, FALSE )} | D14: FALSE
A15: 748 | B15: DSC_0748 PNC1 | C15: {=IF( COUNTIF( SUBSTITUTE(CURADOS!F$2:F1000, ".MOV", ""), SUBSTITUTE(B15, ".MOV", "") )>0, TRUE, FALSE )} | D15: FALSE
A16: 747 | B16: DSC_0747 Sist Prev si | C16: {=IF( COUNTIF( SUBSTITUTE(CURADOS!F$2:F1000, ".MOV", ""), SUBSTITUTE(B16, ".MOV", "") )>0, TRUE, FALSE )} | D16: FALSE
A17: 741 | B17: DSC_0741 CUD tramite2 si | C17: {=IF( COUNTIF( SUBSTITUTE(CURADOS!F$2:F1000, ".MOV", ""), SUBSTITUTE(B17, ".MOV", "") )>0, TRUE, FALSE )} | D17: FALSE
A18: 737 | B18: DSC_0737 Apoyo2 primera parte | C18: {=IF( COUNTIF( SUBSTITUTE(CURADOS!F$2:F1000, ".MOV", ""), SUBSTITUTE(B18, ".MOV", "") )>0, TRUE, FALSE )} | D18: FALSE
A19: 735 | B19: DSC_0735 BF3 si | C19: {=IF( COUNTIF( SUBSTITUTE(CURADOS!F$2:F1000, ".MOV", ""), SUBSTITUTE(B19, ".MOV", "") )>0, TRUE, FALSE )} | D19: FALSE
