Workbook

Sheet RESUMEN
A1: Columna 1 | B1: Videos | C1: Minutos Totales | D1: Minutos Sin Crudo | E1: Minutos Con Crudo | F1: Minutos Hardcoded | G1: Minutos Subtitle
A2: {=UNIQUE(CATALOGO!A2:A1000)} -> Guía de Turismo 2018/2019 | B2: =COUNTIF(CATALOGO!A:A,A2) -> 8 | C2: =SUMIF(CATALOGO!A:A,A2,CATALOGO!D:D)/60 -> 22.316667 | D2: =SUMIFS(CATALOGO!D:D,CATALOGO!A:A,A2,CATALOGO!J:J,"sin match")/60 -> 22.316667 | E2: =(SUMIF(CATALOGO!A:A,A2,CATALOGO!D:D)-SUMIFS(CATALOGO!D:D,CATALOGO!A:A,A2,CATALOGO!J:J,"sin match"))/60 -> 0 | F2: =SUMIFS(CATALOGO!D:D,CATALOGO!A:A,A2,CATALOGO!G:G,TRUE)/60 -> 22.316667 | G2: =SUMIFS(CATALOGO!D:D,CATALOGO!A:A,A2,CATALOGO!I:I,TRUE)/60 -> 0
A3: Guia de Información 2018/2019 | Servicios Sociales Zonales | B3: =COUNTIF(CATALOGO!A:A,A3) -> 3 | C3: =SUMIF(CATALOGO!A:A,A3,CATALOGO!D:D)/60 -> 2.1166667 | D3: =SUMIFS(CATALOGO!D:D,CATALOGO!A:A,A3,CATALOGO!J:J,"sin match")/60 -> 0 | E3: =(SUMIF(CATALOGO!A:A,A3,CATALOGO!D:D)-SUMIFS(CATALOGO!D:D,CATALOGO!A:A,A3,CATALOGO!J:J,"sin match"))/60 -> 2.1166667 | F3: =SUMIFS(CATALOGO!D:D,CATALOGO!A:A,A3,CATALOGO!G:G,TRUE)/60 -> 2.1166667 | G3: =SUMIFS(CATALOGO!D:D,CATALOGO!A:A,A3,CATALOGO!I:I,TRUE)/60 -> 2.1166667
A4: Guía de Información 2018/2019 | Sistema Previsional | B4: =COUNTIF(CATALOGO!A:A,A4) -> 11 | C4: =SUMIF(CATALOGO!A:A,A4,CATALOGO!D:D)/60 -> 5.4166667 | D4: =SUMIFS(CATALOGO!D:D,CATALOGO!A:A,A4,CATALOGO!J:J,"sin match")/60 -> 1.8666667 | E4: =(SUMIF(CATALOGO!A:A,A4,CATALOGO!D:D)-SUMIFS(CATALOGO!D:D,CATALOGO!A:A,A4,CATALOGO!J:J,"sin match"))/60 -> 3.55 | F4: =SUMIFS(CATALOGO!D:D,CATALOGO!A:A,A4,CATALOGO!G:G,TRUE)/60 -> 5.4166667 | G4: =SUMIFS(CATALOGO!D:D,CATALOGO!A:A,A4,CATALOGO!I:I,TRUE)/60 -> 0
A5: Guía de Información 2018/2019 | Vida Independiente | B5: =COUNTIF(CATALOGO!A:A,A5) -> 1 | C5: =SUMIF(CATALOGO!A:A,A5,CATALOGO!D:D)/60 -> 0.48333333 | D5: =SUMIFS(CATALOGO!D:D,CATALOGO!A:A,A5,CATALOGO!J:J,"sin match")/60 -> 0 | E5: =(SUMIF(CATALOGO!A:A,A5,CATALOGO!D:D)-SUMIFS(CATALOGO!D:D,CATALOGO!A:A,A5,CATALOGO!J:J,"sin match"))/60 -> 0.48333333 | F5: =SUMIFS(CATALOGO!D:D,CATALOGO!A:A,A5,CATALOGO!G:G,TRUE)/60 -> 0.48333333 | G5: =SUMIFS(CATALOGO!D:D,CATALOGO!A:A,A5,CATALOGO!I:I,TRUE)/60 -> 0.48333333
A6: Guía de Información 2018/2019 | Participación | B6: =COUNTIF(CATALOGO!A:A,A6) -> 2 | C6: =SUMIF(CATALOGO!A:A,A6,CATALOGO!D:D)/60 -> 1.25 | D6: =SUMIFS(CATALOGO!D:D,CATALOGO!A:A,A6,CATALOGO!J:J,"sin match")/60 -> 1.25 | E6: =(SUMIF(CATALOGO!A:A,A6,CATALOGO!D:D)-SUMIFS(CATALOGO!D:D,CATALOGO!A:A,A6,CATALOGO!J:J,"sin match"))/60 -> 0 | F6: =SUMIFS(CATALOGO!D:D,CATALOGO!A:A,A6,CATALOGO!G:G,TRUE)/60 -> 1.25 | G6: =SUMIFS(CATALOGO!D:D,CATALOGO!A:A,A6,CATALOGO!I:I,TRUE)/60 -> 0
A7: Guía de Información 2018/2019 | Educación | B7: =COUNTIF(CATALOGO!A:A,A7) -> 7 | C7: =SUMIF(CATALOGO!A:A,A7,CATALOGO!D:D)/60 -> 4.55 | D7: =SUMIFS(CATALOGO!D:D,CATALOGO!A:A,A7,CATALOGO!J:J,"sin match")/60 -> 0 | E7: =(SUMIF(CATALOGO!A:A,A7,CATALOGO!D:D)-SUMIFS(CATALOGO!D:D,CATALOGO!A:A,A7,CATALOGO!J:J,"sin match"))/60 -> 4.55 | F7: =SUMIFS(CATALOGO!D:D,CATALOGO!A:A,A7,CATALOGO!G:G,TRUE)/60 -> 4.55 | G7: =SUMIFS(CATALOGO!D:D,CATALOGO!A:A,A7,CATALOGO!I:I,TRUE)/60 -> 3.9333333
A8: Guía de Información 2018/2019 | Transporte | B8: =COUNTIF(CATALOGO!A:A,A8) -> 7 | C8: =SUMIF(CATALOGO!A:A,A8,CATALOGO!D:D)/60 -> 5.25 | D8: =SUMIFS(CATALOGO!D:D,CATALOGO!A:A,A8,CATALOGO!J:J,"sin match")/60 -> 1.1 | E8: =(SUMIF(CATALOGO!A:A,A8,CATALOGO!D:D)-SUMIFS(CATALOGO!D:D,CATALOGO!A:A,A8,CATALOGO!J:J,"sin match"))/60 -> 4.15 | F8: =SUMIFS(CATALOGO!D:D,CATALOGO!A:A,A8,CATALOGO!G:G,TRUE)/60 -> 5.25 | G8: =SUMIFS(CATALOGO!D:D,CATALOGO!A:A,A8,CATALOGO!I:I,TRUE)/60 -> 3.5
A9: Guía de Información 2018/2019 | Accesibilidad | B9: =COUNTIF(CATALOGO!A:A,A9) -> 6 | C9: =SUMIF(CATALOGO!A:A,A9,CATALOGO!D:D)/60 -> 4.65 | D9: =SUMIFS(CATALOGO!D:D,CATALOGO!A:A,A9,CATALOGO!J:J,"sin match")/60 -> 0 | E9: =(SUMIF(CATALOGO!A:A,A9,CATALOGO!D:D)-SUMIFS(CATALOGO!D:D,CATALOGO!A:A,A9,CATALOGO!J:J,"sin match"))/60 -> 4.65 | F9: =SUMIFS(CATALOGO!D:D,CATALOGO!A:A,A9,CATALOGO!G:G,TRUE)/60 -> 4.65 | G9: =SUMIFS(CATALOGO!D:D,CATALOGO!A:A,A9,CATALOGO!I:I,TRUE)/60 -> 4.65
A10: Guía de Información 2018/2019 | Beneficios Fiscales | B10: =COUNTIF(CATALOGO!A:A,A10) -> 2 | C10: =SUMIF(CATALOGO!A:A,A10,CATALOGO!D:D)/60 -> 0.43333333 | D10: =SUMIFS(CATALOGO!D:D,CATALOGO!A:A,A10,CATALOGO!J:J,"sin match")/60 -> 0.43333333 | E10: =(SUMIF(CATALOGO!A:A,A10,CATALOGO!D:D)-SUMIFS(CATALOGO!D:D,CATALOGO!A:A,A10,CATALOGO!J:J,"sin match"))/60 -> 0 | F10: =SUMIFS(CATALOGO!D:D,CATALOGO!A:A,A10,CATALOGO!G:G,TRUE)/60 -> 0.43333333 | G10: =SUMIFS(CATALOGO!D:D,CATALOGO!A:A,A10,CATALOGO!I:I,TRUE)/60 -> 0
A11: Guía de Información 2018/2019 | Trabajo | B11: =COUNTIF(CATALOGO!A:A,A11) -> 5 | C11: =SUMIF(CATALOGO!A:A,A11,CATALOGO!D:D)/60 -> 4.0666667 | D11: =SUMIFS(CATALOGO!D:D,CATALOGO!A:A,A11,CATALOGO!J:J,"sin match")/60 -> 0 | E11: =(SUMIF(CATALOGO!A:A,A11,CATALOGO!D:D)-SUMIFS(CATALOGO!D:D,CATALOGO!A:A,A11,CATALOGO!J:J,"sin match"))/60 -> 4.0666667 | F11: =SUMIFS(CATALOGO!D:D,CATALOGO!A:A,A11,CATALOGO!G:G,TRUE)/60 -> 4.0666667 | G11: =SUMIFS(CATALOGO!D:D,CATALOGO!A:A,A11,CATALOGO!I:I,TRUE)/60 -> 4.0666667
A12: Guía de Información 2018/2019 | Salud | B12: =COUNTIF(CATALOGO!A:A,A12) -> 7 | C12: =SUMIF(CATALOGO!A:A,A12,CATALOGO!D:D)/60 -> 4.2166667 | D12: =SUMIFS(CATALOGO!D:D,CATALOGO!A:A,A12,CATALOGO!J:J,"sin match")/60 -> 1.05 | E12: =(SUMIF(CATALOGO!A:A,A12,CATALOGO!D:D)-SUMIFS(CATALOGO!D:D,CATALOGO!A:A,A12,CATALOGO!J:J,"sin match"))/60 -> 3.1666667 | F12: =SUMIFS(CATALOGO!D:D,CATALOGO!A:A,A12,CATALOGO!G:G,TRUE)/60 -> 4.2166667 | G12: =SUMIFS(CATALOGO!D:D,CATALOGO!A:A,A12,CATALOGO!I:I,TRUE)/60 -> 1.7666667
A13: Guía de Información 2018/2019 | Certificado Único de Discapacidad - CUD | B13: =COUNTIF(CATALOGO!A:A,A13) -> 8 | C13: =SUMIF(CATALOGO!A:A,A13,CATALOGO!D:D)/60 -> 5.5833333 | D13: =SUMIFS(CATALOGO!D:D,CATALOGO!A:A,A13,CATALOGO!J:J,"sin match")/60 -> 0.4 | E13: =(SUMIF(CATALOGO!A:A,A13,CATALOGO!D:D)-SUMIFS(CATALOGO!D:D,CATALOGO!A:A,A13,CATALOGO!J:J,"sin match"))/60 -> 5.1833333 | F13: =SUMIFS(CATALOGO!D:D,CATALOGO!A:A,A13,CATALOGO!G:G,TRUE)/60 -> 5.5833333 | G13: =SUMIFS(CATALOGO!D:D,CATALOGO!A:A,A13,CATALOGO!I:I,TRUE)/60 -> 0
A14: VJORNADA DE VIDA INDEPENDIENTE 2020 | B14: =COUNTIF(CATALOGO!A:A,A14) -> 2 | C14: =SUMIF(CATALOGO!A:A,A14,CATALOGO!D:D)/60 -> 344.18333 | D14: =SUMIFS(CATALOGO!D:D,CATALOGO!A:A,A14,CATALOGO!M:M,"sin match")/60 -> 0 | E14: =(SUMIF(CATALOGO!A:A,A14,CATALOGO!D:D)-SUMIFS(CATALOGO!D:D,CATALOGO!A:A,A14,CATALOGO!M:M,"sin match"))/60 -> 344.18333 | F14: =SUMIFS(CATALOGO!D:D,CATALOGO!A:A,A14,CATALOGO!I:I,TRUE)/60 -> 0 | G14: =SUMIFS(CATALOGO!D:D,CATALOGO!A:A,A14,CATALOGO!L:L,TRUE)/60 -> 0
A15: LEYES SOBRE LA VIOLENCIA CONTRA LAS MUJERES EN LENGUA DE SEÑAS ARGENTINA (LSA) | B15: =COUNTIF(CATALOGO!A:A,A15) -> 34 | C15: =SUMIF(CATALOGO!A:A,A15,CATALOGO!D:D)/60 -> 138.66667 | D15: =SUMIFS(CATALOGO!D:D,CATALOGO!A:A,A15,CATALOGO!M:M,"sin match")/60 -> 0 | E15: =(SUMIF(CATALOGO!A:A,A15,CATALOGO!D:D)-SUMIFS(CATALOGO!D:D,CATALOGO!A:A,A15,CATALOGO!M:M,"sin match"))/60 -> 138.66667 | F15: =SUMIFS(CATALOGO!D:D,CATALOGO!A:A,A15,CATALOGO!I:I,TRUE)/60 -> 0 | G15: =SUMIFS(CATALOGO!D:D,CATALOGO!A:A,A15,CATALOGO!L:L,TRUE)/60 -> 0
A17: SUBTOTAL | C17: =SUM(C2:C13) -> 60.333333 | D17: =SUM(D2:D13) -> 28.416667 | E17: =SUM(E2:E13) -> 31.916667 | F17: =SUM(F2:F12) -> 54.75 | G17: =SUM(G2:G13) -> 20.516667
A19: V Jornada de Vida Independiente - Vivienda con Apoyos: El Derecho a vivir de forma independiente.

Sheet CATALOGO
A1: playlist | B1: yt_id | C1: title | D1: duration_sec | E1: view_count | F1: has_auto_subs | G1: hardcoded_sub | H1: local_file | I1: has_docx_sub | J1: match_status | K1: notas
A2: Guía de Turismo 2018/2019 | B2: ook_O5pd3D0 | C2: Circuito 1: San Nicolás / Casco Histórico | D2: 222 | E2: 95 | F2: FALSE | G2: TRUE | I2: FALSE | J2: sin match | K2: material crudo no encontrado
A3: Guía de Turismo 2018/2019 | B3: VlfX8oURh-s | C3: Circuito 2: San Telmo / La Boca | D3: 276 | E3: 131 | F3: FALSE | G3: TRUE | I3: FALSE | J3: sin match | K3: material crudo no encontrado
A4: Guía de Turismo 2018/2019 | B4: q4S4J59Dvr8 | C4: Circuito 3: Recoleta / Retiro | D4: 190 | E4: 13 | F4: FALSE | G4: TRUE | I4: FALSE | J4: sin match | K4: material crudo no encontrado
A5: Guía de Turismo 2018/2019 | B5: nbHsyDeo3Eo | C5: Circuito 4: Puerto Madero / Balvanera | D5: 270 | E5: 22 | F5: FALSE | G5: TRUE | I5: FALSE | J5: sin match | K5: material crudo no encontrado
A6: Guía de Turismo 2018/2019 | B6: QG7ND5YNfVQ | C6: Circuito 5: Palermo / Belgrano | D6: 196 | E6: 17 | F6: FALSE | G6: TRUE | I6: FALSE | J6: sin match | K6: material crudo no encontrado
A7: Guía de Turismo 2018/2019 | B7: 7az9Z92XonA | C7: Circuito 6: Provincia de Buenos Aires - La Plata | D7: 66 | E7: 28 | F7: FALSE | G7: TRUE | I7: FALSE | J7: sin match | K7: material crudo no encontrado
A8: Guía de Turismo 2018/2019 | B8: EGxhVpFU1OI | C8: Circuito 7: Provincia de Buenos Aires / Bahía Blanca | D8: 59 | E8: 26 | F8: FALSE | G8: TRUE | I8: FALSE | J8: sin match | K8: material crudo no encontrado
A9: Guía de Turismo 2018/2019 | B9: bg8ySVMa71A | C9: Circuito 8 y 9: Provincia de Buenos Aires/ Mar del Plata | D9: 60 | E9: 32 | F9: FALSE | G9: TRUE | I9: FALSE | J9: sin match | K9: material crudo no encontrado
A10: Guia de Información 2018/2019 | Servicios Sociales Zonales | B10: u07hL-EzTpY | C10: 1. Programa Hogares | D10: 52 | E10: 85 | F10: FALSE | G10: TRUE | H10: DSC_0851 p.73.MOV | I10: TRUE | J10: OK
A11: Guia de Información 2018/2019 | Servicios Sociales Zonales | B11: T_vgQJhMWf8 | C11: 2. Apoyos del Gobierno de la Nación | D11: 44 | E11: 172 | F11: FALSE | G11: TRUE | H11: DSC_0856 p.74.MOV | I11: TRUE | J11: OK
A12: Guia de Información 2018/2019 | Servicios Sociales Zonales | B12: 2iYRa7hKg2g | C12: 3. Pedir ayuda técnica | D12: 31 | E12: 130 | F12: FALSE | G12: TRUE | H12: DSC_0858 p. 75 ayuda tecnica.MOV | I12: TRUE | J12: OK
A13: Guía de Información 2018/2019 | Sistema Previsional | B13: KrAliLan0Gs | C13: 1. Sistema previsional | D13: 50 | E13: 334 | F13: FALSE | G13: TRUE | H13: DSC_0701 Titulo Sistema Prev.MOV | I13: FALSE | J13: OK
A14: Guía de Información 2018/2019 | Sistema Previsional | B14: BbiF_2145Es | C14: 2. Pensión no contributiva por discapacidad - PNC | D14: 22 | E14: 302 | F14: FALSE | G14: TRUE | H14: DSC_0749 PNC2.MOV | I14: FALSE | J14: OK
A15: Guía de Información 2018/2019 | Sistema Previsional | B15: MkSTIErbEbk | C15: 3. ¿Cuándo podes cobrar la pensión por discapacidad? | D15: 39 | E15: 225 | F15: FALSE | G15: TRUE | I15: FALSE | J15: sin match
A16: Guía de Información 2018/2019 | Sistema Previsional | B16: 71AmCt5zrr8 | C16: 4. ¿Cómo se tramita la pensión por discapacidad? | D16: 14 | E16: 168 | F16: FALSE | G16: TRUE | I16: FALSE | J16: sin match
A17: Guía de Información 2018/2019 | Sistema Previsional | B17: i1YJ2VoH6_k | C17: 5. Certificado Médico Oficial - CMO | D17: 34 | E17: 728 | F17: FALSE | G17: TRUE | H17: DSC_0765 CMO si.MOV | I17: FALSE | J17: OK
A18: Guía de Información 2018/2019 | Sistema Previsional | B18: lnRWIFwblDw | C18: 6. Asignación universal por hijo con discapacidad | D18: 21 | E18: 510 | F18: FALSE | G18: TRUE | I18: FALSE | J18: sin match
A19: Guía de Información 2018/2019 | Sistema Previsional | B19: O_9wfdgHaW4 | C19: 8. Asignación por hijo con discapacidad | D19: 38 | E19: 279 | F19: FALSE | G19: TRUE | I19: FALSE | J19: sin match
A20: Guía de Información 2018/2019 | Sistema Previsional | B20: V0hm94uW_to | C20: 9. Jubilación por discapacidad | D20: 25 | E20: 162 | F20: FALSE | G20: TRUE | H20: DSC_0775 Jubil disc si.MOV | I20: FALSE | J20: OK
A21: Guía de Información 2018/2019 | Sistema Previsional | B21: DpT8rj_OyXI | C21: 10. Edad jubilación por discapacidad | D21: 21 | E21: 275 | F21: FALSE | G21: TRUE | H21: DSC_0761 PNC dnd si.MOV | I21: FALSE | J21: OK
A22: Guía de Información 2018/2019 | Sistema Previsional | B22: hHqyvAOZpwk | C22: 11. Retiro por invalidez | D22: 33 | E22: 108 | F22: FALSE | G22: TRUE | H22: DSC_0785 Retiro si.MOV | I22: FALSE | J22: OK
A23: Guía de Información 2018/2019 | Sistema Previsional | B23: rX2VatRZzBE | C23: 7. ¿Cuándo podes cobrar la asignación por hijo con discapacidad? | D23: 28 | E23: 922 | F23: FALSE | G23: TRUE | H23: DSC_0771 AHHD si.MOV | I23: FALSE | J23: OK
A24: Guía de Información 2018/2019 | Vida Independiente | B24: kMOBrkojQbw | C24: 1. Banco de Elementos Ortopédicos - BEO | D24: 29 | E24: 148 | F24: FALSE | G24: TRUE | H24: DSC_0882 p,105 beo.MOV | I24: TRUE | J24: OK
A25: Guía de Información 2018/2019 | Participación | B25: J6xUFDqW4BA | C25: 1. Organizaciones Sociedad Civil - OSC | D25: 50 | E25: 104 | F25: FALSE | G25: TRUE | I25: FALSE | J25: sin match
A26: Guía de Información 2018/2019 | Participación | B26: OTmV28NGG5I | C26: 2 - Fortalecimiento ↓ | D26: 25 | E26: 28 | F26: FALSE | G26: TRUE | I26: FALSE | J26: sin match
A27: Guía de Información 2018/2019 | Educación | B27: wSd8jKV42Y8 | C27: 1. Apoyos Educación | D27: 40 | E27: 99 | F27: FALSE | G27: TRUE | H27: DSC_0862 p. 85 apoyos copidis educacion.MOV | I27: TRUE | J27: OK
A28: Guía de Información 2018/2019 | Educación | B28: S2KHEqDAia0 | C28: 2. Materia didáctico Braille ↓ | D28: 46 | E28: 54 | F28: FALSE | G28: TRUE | H28: DSC_0866 p.85 libros escolares accesibles.MOV | I28: TRUE | J28: OK
A29: Guía de Información 2018/2019 | Educación | B29: Psy8y4VfJ2s | C29: 3. Registro Acompañantes No Docentes APND | D29: 57 | E29: 275 | F29: FALSE | G29: TRUE | H29: DSC_0871 p.86 registro docentes apoyo.MOV | I29: TRUE | J29: OK
A30: Guía de Información 2018/2019 | Educación | B30: 5J9xY8gOdUY | C30: 4. Apoyos Ministerio de Educación | D30: 37 | E30: 62 | F30: FALSE | G30: TRUE | H30: DSC_0873 p.87 que apoyos te da el Ministerio de Educacion.MOV | I30: TRUE | J30: OK
A31: Guía de Información 2018/2019 | Educación | B31: Wns-CUyyQL0 | C31: 7. Materiales didácticos | D31: 29 | E31: 60 | F31: FALSE | G31: TRUE | H31: DSC_0881 p.96 material en braille.MOV | I31: TRUE | J31: OK
A32: Guía de Información 2018/2019 | Educación | B32: QlS5zsPqw3k | C32: 6. Escuela hospitalaria o domiciliaria | D32: 27 | E32: 37 | F32: FALSE | G32: TRUE | H32: DSC_0878 p. 95 escuelas hospitalarias.MOV | I32: TRUE | J32: OK
A33: Guía de Información 2018/2019 | Educación | B33: ihpijvrFcbY | C33: 5. Centros educativos de atención y prevención de primera infancia - CEPAPI ↓ | D33: 37 | E33: 152 | F33: FALSE | G33: TRUE | H33: DSC_0875 p.92 cepapi _ rehacer.MOV | I33: FALSE | J33: OK
A34: Guía de Información 2018/2019 | Transporte | B34: vdp9Fh7jj-8 | C34: 6. ¿Cómo pedir la reserva de estacionamiento? ↓ | D34: 45 | F34: FALSE | G34: TRUE | H34: DSC_0824 Reserva estac CONFIRMAR SI.MOV | I34: TRUE | J34: OK
A35: Guía de Información 2018/2019 | Transporte | B35: 3gyP_SIz3T0 | C35: 1. Beneficios transporte | D35: 39 | F35: FALSE | G35: TRUE | H35: DSC_0730 transp4 ver.MOV | I35: FALSE | J35: OK
A36: Guía de Información 2018/2019 | Transporte | B36: gSe9tkhgOT0 | C36: 7. Franquicias | D36: 37 | F36: FALSE | G36: TRUE | H36: DSC_0826 Franquicia si.MOV | I36: TRUE | J36: OK
A37: Guía de Información 2018/2019 | Transporte | B37: Lq8JAf8gTI0 | C37: 2. Pase libre para viajar | D37: 44 | F37: FALSE | G37: TRUE | H37: DSC_0802 Pasaje gratis si.MOV | I37: TRUE | J37: OK
A38: Guía de Información 2018/2019 | Transporte | B38: Gi5dmimT9mg | C38: 3. Peaje libre | D38: 31 | F38: FALSE | G38: TRUE | H38: DSC_0809 Peaje libre si.MOV | I38: TRUE | J38: OK
A39: Guía de Información 2018/2019 | Transporte | B39: DQO5MhSq8ks | C39: 4. Perro guía o de asistencia | D39: 53 | F39: FALSE | G39: TRUE | H39: DSC_0812 Perro guia primera parte.MOV | I39: TRUE | J39: OK
A40: Guía de Información 2018/2019 | Transporte | B40: kcChz0qrXZs | C40: 5. Símbolo Internacional de Acceso | D40: 66 | F40: FALSE | G40: TRUE | I40: FALSE | J40: sin match
...
